Workbook

Sheet global
A1: Country Name | B1: Country Code | C1: WHO_region | D1: WB_region | E1: Income_region | F1: GBD_region | G1: BBS_pop_2022 | H1: AvgSAT_2022 | I1: AvgSAT_2023 | J1: AvgSAT_2024 | K1: GDP_2022 | L1: GDP_2023 | M1: GDP_2024 | N1: perGDP_2022 | O1: perGDP_2023 | P1: perGDP_2024 | Q1: InfVax6m_2022 | R1: InfVax6m_2023 | S1: InfVax6m_2024 | T1: IVC65p_2022 | U1: IVC65p_2023 | V1: IVC65p_2024 | W1: PLGP_2022 | X1: PLGP_2023 | Y1: PLGP_2024 | Z1: PM_2020 | AA1: p14p_2022 | AB1: p14p_2023 | AC1: p14p_2024 | AD1: p65p_2022 | AE1: p65p_2023 | AF1: p65p_2024 | AG1: PopDens_2022 | AH1: PopDens_2023 | AI1: re_2022 | AJ1: re_2023 | AK1: re_2024 | AL1: INT_ARR_2022
A2: Afghanistan | B2: AFG | C2: =VLOOKUP(B2,'[1]who-regions'!$B$1:$D$206,3,FALSE) -> EMR | D2: =VLOOKUP(B2,'[2]Metadata - Countries'!$A$1:$B$266,2,FALSE) -> Middle East & North Africa | E2: =VLOOKUP(B2,'[2]Metadata - Countries'!$A$1:$C$266,3,FALSE) -> Low income | F2: =VLOOKUP(B2,'[3]data-Ib27t'!$A$1:$C$204,2,FALSE) -> #N/A | G2: 55.951941 | H2: =VLOOKUP(B2,[4]tas!$A$2:$H$247,5,FALSE) -> 13.1 | I2: =VLOOKUP(B2,[4]tas!$A$2:$H$247,6,FALSE) -> 13.18 | J2: =VLOOKUP(B2,[4]tas!$A$2:$H$247,7,FALSE) -> 13.22 | K2: 1.4497244e+10 | L2: 1.7152235e+10 | M2: 0 | N2: =VLOOKUP(B2,[2]Data!$B$1:$G$267,4,FALSE) -> 357.26115 | O2: =VLOOKUP(B2,[2]Data!$B$1:$G$267,5,FALSE) -> 413.75789 | P2: =VLOOKUP(B2,[2]Data!$B$1:$G$267,6,FALSE) -> 0 | Q2: =VLOOKUP(B2,[5]Sheet1!$B$421:$K$628,10,FALSE) -> 0 | R2: =VLOOKUP(B2,[5]Sheet1!$B$213:$K$420,10,FALSE) -> 0 | S2: =VLOOKUP(B2,[5]Sheet1!$B$2:$K$207,10,FALSE) -> 0 | T2: =VLOOKUP(B2,[6]Sheet1!$B$421:$K$628,10,FALSE) -> 0 | U2: =VLOOKUP(B2,[6]Sheet1!$B$213:$K$420,10,FALSE) -> 0 | V2: =VLOOKUP(B2,[6]Sheet1!$B$2:$K$212,10,FALSE) -> 0 | W2: 0 | X2: 0 | Y2: 0 | Z2: 46.087094 | AA2: 43.579841 | AB2: 43.226204 | AC2: 42.887506 | AD2: 2.3551424 | AE2: 2.3775375 | AF2: 2.40097 | AG2: 62.215541 | AH2: 63.558501 | AI2: =VLOOKUP(B2,[7]all!$A$2:$I$247,6,FALSE) -> 46.31 | AJ2: =VLOOKUP(B2,[7]all!$A$2:$I$247,7,FALSE) -> 46 | AK2: =VLOOKUP(B2,[7]all!$A$2:$I$247,8,FALSE) -> 46
A3: Albania | B3: ALB | C3: =VLOOKUP(B3,'[1]who-regions'!$B$1:$D$206,3,FALSE) -> EUR | D3: =VLOOKUP(B3,'[2]Metadata - Countries'!$A$1:$B$266,2,FALSE) -> Europe & Central Asia | E3: =VLOOKUP(B3,'[2]Metadata - Countries'!$A$1:$C$266,3,FALSE) -> Upper middle income | G3: 99.299266 | H3: =VLOOKUP(B3,[4]tas!$A$2:$H$247,5,FALSE) -> 13.35 | I3: =VLOOKUP(B3,[4]tas!$A$2:$H$247,6,FALSE) -> 13.4 | J3: =VLOOKUP(B3,[4]tas!$A$2:$H$247,7,FALSE) -> 13.41 | K3: 1.9017244e+10 | L3: 2.354718e+10 | M3: 2.7177736e+10 | N3: =VLOOKUP(B3,[2]Data!$B$1:$G$267,4,FALSE) -> 7756.9619 | O3: =VLOOKUP(B3,[2]Data!$B$1:$G$267,5,FALSE) -> 9730.8692 | P3: =VLOOKUP(B3,[2]Data!$B$1:$G$267,6,FALSE) -> 11377.776 | Q3: =VLOOKUP(B3,[5]Sheet1!$B$421:$K$628,10,FALSE) -> 0 | R3: =VLOOKUP(B3,[5]Sheet1!$B$213:$K$420,10,FALSE) -> 0 | S3: =VLOOKUP(B3,[5]Sheet1!$B$2:$K$207,10,FALSE) -> 0 | T3: =VLOOKUP(B3,[6]Sheet1!$B$421:$K$628,10,FALSE) -> 25.08 | U3: =VLOOKUP(B3,[6]Sheet1!$B$213:$K$420,10,FALSE) -> 25.08 | V3: =VLOOKUP(B3,[6]Sheet1!$B$2:$K$212,10,FALSE) -> 23.72 | W3: 85.972977 | X3: 86.650452 | Y3: 0 | Z3: 15.707004 | AA3: 17.222472 | AB3: 17.041973 | AC3: 16.840783 | AD3: 15.776338 | AE3: 16.302 | AF3: 16.922756 | AG3: 101.37551 | AH3: 100.21796 | AI3: =VLOOKUP(B3,[7]all!$A$2:$I$247,6,FALSE) -> 71.54 | AJ3: =VLOOKUP(B3,[7]all!$A$2:$I$247,7,FALSE) -> 71.76 | AK3: =VLOOKUP(B3,[7]all!$A$2:$I$247,8,FALSE) -> 71.81
A4: Algeria | B4: DZA | C4: =VLOOKUP(B4,'[1]who-regions'!$B$1:$D$206,3,FALSE) -> AFR | D4: =VLOOKUP(B4,'[2]Metadata - Countries'!$A$1:$B$266,2,FALSE) -> Middle East & North Africa | E4: =VLOOKUP(B4,'[2]Metadata - Countries'!$A$1:$C$266,3,FALSE) -> Upper middle income | G4: 85.826289 | H4: =VLOOKUP(B4,[4]tas!$A$2:$H$247,5,FALSE) -> 24.18 | I4: =VLOOKUP(B4,[4]tas!$A$2:$H$247,6,FALSE) -> 24.12 | J4: =VLOOKUP(B4,[4]tas!$A$2:$H$247,7,FALSE) -> 24.2 | K4: 2.2563846e+11 | L4: 2.4762616e+11 | M4: 2.6361979e+11 | N4: =VLOOKUP(B4,[2]Data!$B$1:$G$267,4,FALSE) -> 4960.3033 | O4: =VLOOKUP(B4,[2]Data!$B$1:$G$267,5,FALSE) -> 5370.4772 | P4: =VLOOKUP(B4,[2]Data!$B$1:$G$267,6,FALSE) -> 5752.9908 | Q4: =VLOOKUP(B4,[5]Sheet1!$B$421:$K$628,10,FALSE) -> 0 | R4: =VLOOKUP(B4,[5]Sheet1!$B$213:$K$420,10,FALSE) -> 0 | S4: =VLOOKUP(B4,[5]Sheet1!$B$2:$K$207,10,FALSE) -> 0 | T4: =VLOOKUP(B4,[6]Sheet1!$B$421:$K$628,10,FALSE) -> 0 | U4: =VLOOKUP(B4,[6]Sheet1!$B$213:$K$420,10,FALSE) -> 0 | V4: =VLOOKUP(B4,[6]Sheet1!$B$2:$K$212,10,FALSE) -> 0 | W4: 0 | X4: 0 | Y4: 0 | Z4: 25.552656 | AA4: 30.841192 | AB4: 30.639348 | AC4: 30.329005 | AD4: 6.1869635 | AE4: 6.3768587 | AF4: 6.5822121 | AG4: 19.094187 | AH4: 19.38256 | AI4: =VLOOKUP(B4,[7]all!$A$2:$I$247,6,FALSE) -> 30.14 | AJ4: =VLOOKUP(B4,[7]all!$A$2:$I$247,7,FALSE) -> 30.19 | AK4: =VLOOKUP(B4,[7]all!$A$2:$I$247,8,FALSE) -> 30.4
A5: American Samoa | B5: ASM | C5: =VLOOKUP(B5,'[1]who-regions'!$B$1:$D$206,3,FALSE) -> WPR | D5: =VLOOKUP(B5,'[2]Metadata - Countries'!$A$1:$B$266,2,FALSE) -> East Asia & Pacific | E5: =VLOOKUP(B5,'[2]Metadata - Countries'!$A$1:$C$266,3,FALSE) -> High income | G5: 54.145299 | H5: =VLOOKUP(B5,[4]tas!$A$2:$H$247,5,FALSE) -> 27 | I5: =VLOOKUP(B5,[4]tas!$A$2:$H$247,6,FALSE) -> 27.01 | J5: =VLOOKUP(B5,[4]tas!$A$2:$H$247,7,FALSE) -> 27.07 | K5: 871000000 | L5: 0 | M5: 0 | N5: =VLOOKUP(B5,[2]Data!$B$1:$G$267,4,FALSE) -> 18017.459 | O5: =VLOOKUP(B5,[2]Data!$B$1:$G$267,5,FALSE) -> 0 | P5: =VLOOKUP(B5,[2]Data!$B$1:$G$267,6,FALSE) -> 0 | Q5: =VLOOKUP(B5,[5]Sheet1!$B$421:$K$628,10,FALSE) -> #N/A | R5: =VLOOKUP(B5,[5]Sheet1!$B$213:$K$420,10,FALSE) -> #N/A | S5: =VLOOKUP(B5,[5]Sheet1!$B$2:$K$207,10,FALSE) -> #N/A | T5: =VLOOKUP(B5,[6]Sheet1!$B$421:$K$628,10,FALSE) -> #N/A | U5: =VLOOKUP(B5,[6]Sheet1!$B$213:$K$420,10,FALSE) -> #N/A | V5: =VLOOKUP(B5,[6]Sheet1!$B$2:$K$212,10,FALSE) -> #N/A | W5: 0 | X5: 0 | Y5: 0 | Z5: 6.7151474 | AA5: 28.065947 | AB5: 27.510995 | AC5: 27.008446 | AD5: 7.1036273 | AE5: 7.5503462 | AF5: 8.0444777 | AG5: 241.71 | AH5: 237.605 | AI5: =VLOOKUP(B5,[7]all!$A$2:$I$247,6,FALSE) -> 82.4 | AJ5: =VLOOKUP(B5,[7]all!$A$2:$I$247,7,FALSE) -> 82.3 | AK5: =VLOOKUP(B5,[7]all!$A$2:$I$247,8,FALSE) -> 82.44
A6: Andorra | B6: AND | C6: =VLOOKUP(B6,'[1]who-regions'!$B$1:$D$206,3,FALSE) -> EUR | D6: =VLOOKUP(B6,'[2]Metadata - Countries'!$A$1:$B$266,2,FALSE) -> Europe & Central Asia | E6: =VLOOKUP(B6,'[2]Metadata - Countries'!$A$1:$C$266,3,FALSE) -> High income | G6: 100 | H6: =VLOOKUP(B6,[4]tas!$A$2:$H$247,5,FALSE) -> 6.04 | I6: =VLOOKUP(B6,[4]tas!$A$2:$H$247,6,FALSE) -> 5.97 | J6: =VLOOKUP(B6,[4]tas!$A$2:$H$247,7,FALSE) -> 5.96 | K6: 3.3806126e+09 | L6: 3.7850673e+09 | M6: 4.0398444e+09 | N6: =VLOOKUP(B6,[2]Data!$B$1:$G$267,4,FALSE) -> 42414.048 | O6: =VLOOKUP(B6,[2]Data!$B$1:$G$267,5,FALSE) -> 46812.426 | P6: =VLOOKUP(B6,[2]Data!$B$1:$G$267,6,FALSE) -> 49303.649 | Q6: =VLOOKUP(B6,[5]Sheet1!$B$421:$K$628,10,FALSE) -> 0 | R6: =VLOOKUP(B6,[5]Sheet1!$B$213:$K$420,10,FALSE) -> 0 | S6: =VLOOKUP(B6,[5]Sheet1!$B$2:$K$207,10,FALSE) -> 0 | T6: =VLOOKUP(B6,[6]Sheet1!$B$421:$K$628,10,FALSE) -> 41.62 | U6: =VLOOKUP(B6,[6]Sheet1!$B$213:$K$420,10,FALSE) -> 37.12 | V6: =VLOOKUP(B6,[6]Sheet1!$B$2:$K$212,10,FALSE) -> 27.34 | W6: 0 | X6: 0 | Y6: 0 | Z6: 9.0802806 | AA6: 12.656044 | AB6: 12.2477 | AC6: 11.885278 | AD6: 14.968948 | AE6: 15.418151 | AF6: 15.94569 | AG6: 169.58511 | AH6: 172.03404 | AI6: =VLOOKUP(B6,[7]all!$A$2:$I$247,6,FALSE) -> 73.99 | AJ6: =VLOOKUP(B6,[7]all!$A$2:$I$247,7,FALSE) -> 74.74 | AK6: =VLOOKUP(B6,[7]all!$A$2:$I$247,8,FALSE) -> 74.02
A7: Angola | B7: AGO | C7: =VLOOKUP(B7,'[1]who-regions'!$B$1:$D$206,3,FALSE) -> AFR | D7: =VLOOKUP(B7,'[2]Metadata - Countries'!$A$1:$B$266,2,FALSE) -> Sub-Saharan Africa | E7: =VLOOKUP(B7,'[2]Metadata - Countries'!$A$1:$C$266,3,FALSE) -> Lower middle income | G7: 52.177276 | H7: =VLOOKUP(B7,[4]tas!$A$2:$H$247,5,FALSE) -> 23.2 | I7: =VLOOKUP(B7,[4]tas!$A$2:$H$247,6,FALSE) -> 23.23 | J7: =VLOOKUP(B7,[4]tas!$A$2:$H$247,7,FALSE) -> 23.29 | K7: 1.0439975e+11 | L7: 8.4875162e+10 | M7: 8.0396942e+10 | N7: =VLOOKUP(B7,[2]Data!$B$1:$G$267,4,FALSE) -> 3682.1132 | O7: =VLOOKUP(B7,[2]Data!$B$1:$G$267,5,FALSE) -> 2916.1366 | P7: =VLOOKUP(B7,[2]Data!$B$1:$G$267,6,FALSE) -> 2665.8744 | Q7: =VLOOKUP(B7,[5]Sheet1!$B$421:$K$628,10,FALSE) -> 0 | R7: =VLOOKUP(B7,[5]Sheet1!$B$213:$K$420,10,FALSE) -> 0 | S7: =VLOOKUP(B7,[5]Sheet1!$B$2:$K$207,10,FALSE) -> 0 | T7: =VLOOKUP(B7,[6]Sheet1!$B$421:$K$628,10,FALSE) -> 0 | U7: =VLOOKUP(B7,[6]Sheet1!$B$213:$K$420,10,FALSE) -> 0 | V7: =VLOOKUP(B7,[6]Sheet1!$B$2:$K$212,10,FALSE) -> 0 | W7: 0 | X7: 0 | Y7: 0 | Z7: 25.145238 | AA7: 44.757877 | AB7: 44.572265 | AC7: 44.350963 | AD7: 2.7733386 | AE7: 2.8114494 | AF7: 2.8524212 | AG7: 28.583484 | AH7: 29.477746 | AI7: =VLOOKUP(B7,[7]all!$A$2:$I$247,6,FALSE) -> 60.14 | AJ7: =VLOOKUP(B7,[7]all!$A$2:$I$247,7,FALSE) -> 59.78 | AK7: =VLOOKUP(B7,[7]all!$A$2:$I$247,8,FALSE) -> 59.98
A8: Antigua and Barbuda | B8: ATG | C8: =VLOOKUP(B8,'[1]who-regions'!$B$1:$D$206,3,FALSE) -> AMR | D8: =VLOOKUP(B8,'[2]Metadata - Countries'!$A$1:$B$266,2,FALSE) -> Latin America & Caribbean | E8: =VLOOKUP(B8,'[2]Metadata - Countries'!$A$1:$C$266,3,FALSE) -> High income | G8: 97.403719 | H8: =VLOOKUP(B8,[4]tas!$A$2:$H$247,5,FALSE) -> 26.52 | I8: =VLOOKUP(B8,[4]tas!$A$2:$H$247,6,FALSE) -> 26.56 | J8: =VLOOKUP(B8,[4]tas!$A$2:$H$247,7,FALSE) -> 26.61 | K8: 1.8665667e+09 | L8: 2.0057852e+09 | M8: 2.2248148e+09 | N8: =VLOOKUP(B8,[2]Data!$B$1:$G$267,4,FALSE) -> 20105.199 | O8: =VLOOKUP(B8,[2]Data!$B$1:$G$267,5,FALSE) -> 21494.547 | P8: =VLOOKUP(B8,[2]Data!$B$1:$G$267,6,FALSE) -> 23542.453 | Q8: =VLOOKUP(B8,[5]Sheet1!$B$421:$K$628,10,FALSE) -> 0 | R8: =VLOOKUP(B8,[5]Sheet1!$B$213:$K$420,10,FALSE) -> 0 | S8: =VLOOKUP(B8,[5]Sheet1!$B$2:$K$207,10,FALSE) -> 0 | T8: =VLOOKUP(B8,[6]Sheet1!$B$421:$K$628,10,FALSE) -> 0 | U8: =VLOOKUP(B8,[6]Sheet1!$B$213:$K$420,10,FALSE) -> 0 | V8: =VLOOKUP(B8,[6]Sheet1!$B$2:$K$212,10,FALSE) -> 0 | W8: 0 | X8: 0 | Y8: 0 | Z8: 19.69827 | AA8: 18.573352 | AB8: 18.217231 | AC8: 17.799651 | AD8: 10.728673 | AE8: 11.238755 | AF8: 11.784497 | AG8: 211 | AH8: 212.08182 | AI8: =VLOOKUP(B8,[7]all!$A$2:$I$247,6,FALSE) -> 80.04 | AJ8: =VLOOKUP(B8,[7]all!$A$2:$I$247,7,FALSE) -> 80.09 | AK8: =VLOOKUP(B8,[7]all!$A$2:$I$247,8,FALSE) -> 79.98
A9: Argentina | B9: ARG | C9: =VLOOKUP(B9,'[1]who-regions'!$B$1:$D$206,3,FALSE) -> AMR | D9: =VLOOKUP(B9,'[2]Metadata - Countries'!$A$1:$B$266,2,FALSE) -> Latin America & Caribbean | E9: =VLOOKUP(B9,'[2]Metadata - Countries'!$A$1:$C$266,3,FALSE) -> Upper middle income | G9: 0 | H9: =VLOOKUP(B9,[4]tas!$A$2:$H$247,5,FALSE) -> 15.52 | I9: =VLOOKUP(B9,[4]tas!$A$2:$H$247,6,FALSE) -> 15.52 | J9: =VLOOKUP(B9,[4]tas!$A$2:$H$247,7,FALSE) -> 15.65 | K9: 6.3279007e+11 | L9: 6.4607528e+11 | M9: 6.3326669e+11 | N9: =VLOOKUP(B9,[2]Data!$B$1:$G$267,4,FALSE) -> 13962.189 | O9: =VLOOKUP(B9,[2]Data!$B$1:$G$267,5,FALSE) -> 14261.847 | P9: =VLOOKUP(B9,[2]Data!$B$1:$G$267,6,FALSE) -> 13969.784 | Q9: =VLOOKUP(B9,[5]Sheet1!$B$421:$K$628,10,FALSE) -> 0 | R9: =VLOOKUP(B9,[5]Sheet1!$B$213:$K$420,10,FALSE) -> 0 | S9: =VLOOKUP(B9,[5]Sheet1!$B$2:$K$207,10,FALSE) -> 0 | T9: =VLOOKUP(B9,[6]Sheet1!$B$421:$K$628,10,FALSE) -> 75.85 | U9: =VLOOKUP(B9,[6]Sheet1!$B$213:$K$420,10,FALSE) -> 12.19 | V9: =VLOOKUP(B9,[6]Sheet1!$B$2:$K$212,10,FALSE) -> 0 | W9: 0 | X9: 0 | Y9: 0 | Z9: 14.908174 | AA9: 22.750746 | AB9: 22.190657 | AC9: 21.603943 | AD9: 12.03408 | AE9: 12.203022 | AF9: 12.416004 | AG9: 16.592272 | AH9: 16.639956 | AI9: =VLOOKUP(B9,[7]all!$A$2:$I$247,6,FALSE) -> 58.82 | AJ9: =VLOOKUP(B9,[7]all!$A$2:$I$247,7,FALSE) -> 58.82 | AK9: =VLOOKUP(B9,[7]all!$A$2:$I$247,8,FALSE) -> 58.14 | AL9: 113132.4
A10: Armenia | B10: ARM | C10: =VLOOKUP(B10,'[1]who-regions'!$B$1:$D$206,3,FALSE) -> EUR | D10: =VLOOKUP(B10,'[2]Metadata - Countries'!$A$1:$B$266,2,FALSE) -> Europe & Central Asia | E10: =VLOOKUP(B10,'[2]Metadata - Countries'!$A$1:$C$266,3,FALSE) -> Upper middle income | G10: 93.979714 | H10: =VLOOKUP(B10,[4]tas!$A$2:$H$247,5,FALSE) -> 7.59 | I10: =VLOOKUP(B10,[4]tas!$A$2:$H$247,6,FALSE) -> 7.58 | J10: =VLOOKUP(B10,[4]tas!$A$2:$H$247,7,FALSE) -> 7.75 | K10: 1.9513507e+10 | L10: 2.408575e+10 | M10: 2.5786586e+10 | N10: =VLOOKUP(B10,[2]Data!$B$1:$G$267,4,FALSE) -> 6571.9745 | O10: =VLOOKUP(B10,[2]Data!$B$1:$G$267,5,FALSE) -> 8159.0872 | P10: =VLOOKUP(B10,[2]Data!$B$1:$G$267,6,FALSE) -> 8556.2141 | Q10: =VLOOKUP(B10,[5]Sheet1!$B$421:$K$628,10,FALSE) -> 0 | R10: =VLOOKUP(B10,[5]Sheet1!$B$213:$K$420,10,FALSE) -> 0 | S10: =VLOOKUP(B10,[5]Sheet1!$B$2:$K$207,10,FALSE) -> 0 | T10: =VLOOKUP(B10,[6]Sheet1!$B$421:$K$628,10,FALSE) -> 17.3 | U10: =VLOOKUP(B10,[6]Sheet1!$B$213:$K$420,10,FALSE) -> 18.1 | V10: =VLOOKUP(B10,[6]Sheet1!$B$2:$K$212,10,FALSE) -> 20.13 | W10: 98.477921 | X10: 0 | Y10: 0 | Z10: 30.579633 | AA10: 19.862563 | AB10: 19.545334 | AC10: 19.237077 | AD10: 12.915158 | AE10: 13.211046 | AF10: 13.702769 | AG10: 105.29705 | AH10: 105.11911 | AI10: =VLOOKUP(B10,[7]all!$A$2:$I$247,6,FALSE) -> 69.54 | AJ10: =VLOOKUP(B10,[7]all!$A$2:$I$247,7,FALSE) -> 69.4 | AK10: =VLOOKUP(B10,[7]all!$A$2:$I$247,8,FALSE) -> 69.62
A11: Aruba | B11: ABW | C11: None | D11: =VLOOKUP(B11,'[2]Metadata - Countries'!$A$1:$B$266,2,FALSE) -> Latin America & Caribbean | E11: =VLOOKUP(B11,'[2]Metadata - Countries'!$A$1:$C$266,3,FALSE) -> High income | G11: 98.840002 | H11: =VLOOKUP(B11,[4]tas!$A$2:$H$247,5,FALSE) -> 27.11 | I11: =VLOOKUP(B11,[4]tas!$A$2:$H$247,6,FALSE) -> 27.07 | J11: =VLOOKUP(B11,[4]tas!$A$2:$H$247,7,FALSE) -> 27.13 | K11: 3.2793435e+09 | L11: 3.6485731e+09 | M11: 0 | N11: =VLOOKUP(B11,[2]Data!$B$1:$G$267,4,FALSE) -> 30975.999 | O11: =VLOOKUP(B11,[2]Data!$B$1:$G$267,5,FALSE) -> 35718.753 | P11: =VLOOKUP(B11,[2]Data!$B$1:$G$267,6,FALSE) -> 39498.594 | Q11: =VLOOKUP(B11,[5]Sheet1!$B$421:$K$628,10,FALSE) -> 0 | R11: =VLOOKUP(B11,[5]Sheet1!$B$213:$K$420,10,FALSE) -> 0 | S11: =VLOOKUP(B11,[5]Sheet1!$B$2:$K$207,10,FALSE) -> 0 | T11: =VLOOKUP(B11,[6]Sheet1!$B$421:$K$628,10,FALSE) -> 0 | U11: =VLOOKUP(B11,[6]Sheet1!$B$213:$K$420,10,FALSE) -> 0 | V11: =VLOOKUP(B11,[6]Sheet1!$B$2:$K$212,10,FALSE) -> 0 | W11: 0 | X11: 0 | Y11: 0 | Z11: 0 | AA11: 17.544674 | AB11: 17.185249 | AC11: 16.844876 | AD11: 15.70021 | AE11: 16.369043 | AF11: 17.056322 | AG11: 596.16667 | AH11: 596.43889 | AI11: =VLOOKUP(B11,[7]all!$A$2:$I$247,6,FALSE) -> 84.21 | AJ11: =VLOOKUP(B11,[7]all!$A$2:$I$247,7,FALSE) -> 84.23 | AK11: =VLOOKUP(B11,[7]all!$A$2:$I$247,8,FALSE) -> 84.25
A12: Australia | B12: AUS | C12: =VLOOKUP(B12,'[1]who-regions'!$B$1:$D$206,3,FALSE) -> WPR | D12: =VLOOKUP(B12,'[2]Metadata - Countries'!$A$1:$B$266,2,FALSE) -> East Asia & Pacific | E12: =VLOOKUP(B12,'[2]Metadata - Countries'!$A$1:$C$266,3,FALSE) -> High income | G12: 100 | H12: =VLOOKUP(B12,[4]tas!$A$2:$H$247,5,FALSE) -> 22.83 | I12: =VLOOKUP(B12,[4]tas!$A$2:$H$247,6,FALSE) -> 22.86 | J12: =VLOOKUP(B12,[4]tas!$A$2:$H$247,7,FALSE) -> 22.94 | K12: 1.6908582e+12 | L12: 1.7280573e+12 | M12: 1.7521933e+12 | N12: =VLOOKUP(B12,[2]Data!$B$1:$G$267,4,FALSE) -> 65169.519 | O12: =VLOOKUP(B12,[2]Data!$B$1:$G$267,5,FALSE) -> 65058.377 | P12: =VLOOKUP(B12,[2]Data!$B$1:$G$267,6,FALSE) -> 64603.986 | Q12: =VLOOKUP(B12,[5]Sheet1!$B$421:$K$628,10,FALSE) -> 0 | R12: =VLOOKUP(B12,[5]Sheet1!$B$213:$K$420,10,FALSE) -> 0 | S12: =VLOOKUP(B12,[5]Sheet1!$B$2:$K$207,10,FALSE) -> 0 | T12: =VLOOKUP(B12,[6]Sheet1!$B$421:$K$628,10,FALSE) -> 0 | U12: =VLOOKUP(B12,[6]Sheet1!$B$213:$K$420,10,FALSE) -> 0 | V12: =VLOOKUP(B12,[6]Sheet1!$B$2:$K$212,10,FALSE) -> 61.1 | W12: 0 | X12: 0 | Y12: 0 | Z12: 8.2517175 | AA12: 18.235542 | AB12: 18.030283 | AC12: 17.841848 | AD12: 17.075032 | AE12: 17.384025 | AF12: 17.730016 | AG12: 3.3819984 | AH12: 3.4649906 | AI12: =VLOOKUP(B12,[7]all!$A$2:$I$247,6,FALSE) -> 47.17 | AJ12: =VLOOKUP(B12,[7]all!$A$2:$I$247,7,FALSE) -> 47.01 | AK12: =VLOOKUP(B12,[7]all!$A$2:$I$247,8,FALSE) -> 46.84 | AL12: 309626
A13: Austria | B13: AUT | C13: =VLOOKUP(B13,'[1]who-regions'!$B$1:$D$206,3,FALSE) -> EUR | D13: =VLOOKUP(B13,'[2]Metadata - Countries'!$A$1:$B$266,2,FALSE) -> Europe & Central Asia | E13: =VLOOKUP(B13,'[2]Metadata - Countries'!$A$1:$C$266,3,FALSE) -> High income | G13: 99.972367 | H13: =VLOOKUP(B13,[4]tas!$A$2:$H$247,5,FALSE) -> 7.62 | I13: =VLOOKUP(B13,[4]tas!$A$2:$H$247,6,FALSE) -> 7.53 | J13: =VLOOKUP(B13,[4]tas!$A$2:$H$247,7,FALSE) -> 7.47 | K13: 4.7177363e+11 | L13: 5.116852e+11 | M13: 5.2164247e+11 | N13: =VLOOKUP(B13,[2]Data!$B$1:$G$267,4,FALSE) -> 52336.773 | O13: =VLOOKUP(B13,[2]Data!$B$1:$G$267,5,FALSE) -> 56579.504 | P13: =VLOOKUP(B13,[2]Data!$B$1:$G$267,6,FALSE) -> 58268.879 | Q13: =VLOOKUP(B13,[5]Sheet1!$B$421:$K$628,10,FALSE) -> 0 | R13: =VLOOKUP(B13,[5]Sheet1!$B$213:$K$420,10,FALSE) -> 0 | S13: =VLOOKUP(B13,[5]Sheet1!$B$2:$K$207,10,FALSE) -> 0 | T13: =VLOOKUP(B13,[6]Sheet1!$B$421:$K$628,10,FALSE) -> 0 | U13: =VLOOKUP(B13,[6]Sheet1!$B$213:$K$420,10,FALSE) -> 23.46 | V13: =VLOOKUP(B13,[6]Sheet1!$B$2:$K$212,10,FALSE) -> 0 | W13: 0 | X13: 0 | Y13: 0 | Z13: 10.933514 | AA13: 14.346154 | AB13: 14.302636 | AC13: 14.228002 | AD13: 19.789751 | AE13: 20.16402 | AF13: 20.606403 | AG13: 109.57163 | AH13: 110.66119 | AI13: =VLOOKUP(B13,[7]all!$A$2:$I$247,6,FALSE) -> 77.15 | AJ13: =VLOOKUP(B13,[7]all!$A$2:$I$247,7,FALSE) -> 77.28 | AK13: =VLOOKUP(B13,[7]all!$A$2:$I$247,8,FALSE) -> 77.08
A14: Azerbaijan | B14: AZE | C14: =VLOOKUP(B14,'[1]who-regions'!$B$1:$D$206,3,FALSE) -> EUR | D14: =VLOOKUP(B14,'[2]Metadata - Countries'!$A$1:$B$266,2,FALSE) -> Europe & Central Asia | E14: =VLOOKUP(B14,'[2]Metadata - Countries'!$A$1:$C$266,3,FALSE) -> Upper middle income | G14: 0 | H14: =VLOOKUP(B14,[4]tas!$A$2:$H$247,5,FALSE) -> 13.13 | I14: =VLOOKUP(B14,[4]tas!$A$2:$H$247,6,FALSE) -> 13.09 | J14: =VLOOKUP(B14,[4]tas!$A$2:$H$247,7,FALSE) -> 13.24 | K14: 7.8807471e+10 | L14: 7.2428471e+10 | M14: 7.4315882e+10 | N14: =VLOOKUP(B14,[2]Data!$B$1:$G$267,4,FALSE) -> 7770.5942 | O14: =VLOOKUP(B14,[2]Data!$B$1:$G$267,5,FALSE) -> 7133.0284 | P14: =VLOOKUP(B14,[2]Data!$B$1:$G$267,6,FALSE) -> 7283.8499 | Q14: =VLOOKUP(B14,[5]Sheet1!$B$421:$K$628,10,FALSE) -> 0 | R14: =VLOOKUP(B14,[5]Sheet1!$B$213:$K$420,10,FALSE) -> 0 | S14: =VLOOKUP(B14,[5]Sheet1!$B$2:$K$207,10,FALSE) -> 0 | T14: =VLOOKUP(B14,[6]Sheet1!$B$421:$K$628,10,FALSE) -> 0.52 | U14: =VLOOKUP(B14,[6]Sheet1!$B$213:$K$420,10,FALSE) -> 0.44 | V14: =VLOOKUP(B14,[6]Sheet1!$B$2:$K$212,10,FALSE) -> 0.36 | W14: 99.041634 | X14: 99.33773 | Y14: 0 | Z14: 21.727 | AA14: 22.797603 | AB14: 22.344439 | AC14: 21.811634 | AD14: 7.526514 | AE14: 8.0105487 | AF14: 8.5557671 | AG14: 122.70727 | AH14: 122.85491 | AI14: =VLOOKUP(B14,[7]all!$A$2:$I$247,6,FALSE) -> 68.6 | AJ14: =VLOOKUP(B14,[7]all!$A$2:$I$247,7,FALSE) -> 68.43 | AK14: =VLOOKUP(B14,[7]all!$A$2:$I$247,8,FALSE) -> 68.73 | AL14: 17778
A15: Bahamas, The | B15: BHS | C15: =VLOOKUP(B15,'[1]who-regions'!$B$1:$D$206,3,FALSE) -> AMR | D15: =VLOOKUP(B15,'[2]Metadata - Countries'!$A$1:$B$266,2,FALSE) -> Latin America & Caribbean | E15: =VLOOKUP(B15,'[2]Metadata - Countries'!$A$1:$C$266,3,FALSE) -> High income | G15: 0 | H15: =VLOOKUP(B15,[4]tas!$A$2:$H$247,5,FALSE) -> 25.84 | I15: =VLOOKUP(B15,[4]tas!$A$2:$H$247,6,FALSE) -> 25.88 | J15: =VLOOKUP(B15,[4]tas!$A$2:$H$247,7,FALSE) -> 25.89 | K15: 13896800000 | L15: 15271300000 | M15: 15832800000 | N15: =VLOOKUP(B15,[2]Data!$B$1:$G$267,4,FALSE) -> 34957.161 | O15: =VLOOKUP(B15,[2]Data!$B$1:$G$267,5,FALSE) -> 38231.774 | P15: =VLOOKUP(B15,[2]Data!$B$1:$G$267,6,FALSE) -> 39455.447 | Q15: =VLOOKUP(B15,[5]Sheet1!$B$421:$K$628,10,FALSE) -> 0 | R15: =VLOOKUP(B15,[5]Sheet1!$B$213:$K$420,10,FALSE) -> 0 | S15: =VLOOKUP(B15,[5]Sheet1!$B$2:$K$207,10,FALSE) -> 0 | T15: =VLOOKUP(B15,[6]Sheet1!$B$421:$K$628,10,FALSE) -> 0 | U15: =VLOOKUP(B15,[6]Sheet1!$B$213:$K$420,10,FALSE) -> 0 | V15: =VLOOKUP(B15,[6]Sheet1!$B$2:$K$212,10,FALSE) -> 0 | W15: 0 | X15: 0 | Y15: 0 | Z15: 18.939392 | AA15: 18.751266 | AB15: 18.328262 | AC15: 17.912795 | AD15: 11.252118 | AE15: 11.497958 | AF15: 11.775854 | AG15: 39.714086 | AH15: 39.904096 | AI15: =VLOOKUP(B15,[7]all!$A$2:$I$247,6,FALSE) -> 76.76 | AJ15: =VLOOKUP(B15,[7]all!$A$2:$I$247,7,FALSE) -> 76.78 | AK15: =VLOOKUP(B15,[7]all!$A$2:$I$247,8,FALSE) -> 76.76
A16: Bahrain | B16: BHR | C16: =VLOOKUP(B16,'[1]who-regions'!$B$1:$D$206,3,FALSE) -> EMR | D16: =VLOOKUP(B16,'[2]Metadata - Countries'!$A$1:$B$266,2,FALSE) -> Middle East & North Africa | E16: =VLOOKUP(B16,'[2]Metadata - Countries'!$A$1:$C$266,3,FALSE) -> High income | G16: 100 | H16: =VLOOKUP(B16,[4]tas!$A$2:$H$247,5,FALSE) -> 26.92 | I16: =VLOOKUP(B16,[4]tas!$A$2:$H$247,6,FALSE) -> 26.95 | J16: =VLOOKUP(B16,[4]tas!$A$2:$H$247,7,FALSE) -> 27.03 | K16: 4.6458191e+10 | L16: 4.6192261e+10 | M16: 4.7736702e+10 | N16: =VLOOKUP(B16,[2]Data!$B$1:$G$267,4,FALSE) -> 30470.522 | O16: =VLOOKUP(B16,[2]Data!$B$1:$G$267,5,FALSE) -> 29290.128 | P16: =VLOOKUP(B16,[2]Data!$B$1:$G$267,6,FALSE) -> 29653.568 | Q16: =VLOOKUP(B16,[5]Sheet1!$B$421:$K$628,10,FALSE) -> 0 | R16: =VLOOKUP(B16,[5]Sheet1!$B$213:$K$420,10,FALSE) -> 0 | S16: =VLOOKUP(B16,[5]Sheet1!$B$2:$K$207,10,FALSE) -> 0 | T16: =VLOOKUP(B16,[6]Sheet1!$B$421:$K$628,10,FALSE) -> 0 | U16: =VLOOKUP(B16,[6]Sheet1!$B$213:$K$420,10,FALSE) -> 6.4 | V16: =VLOOKUP(B16,[6]Sheet1!$B$2:$K$212,10,FALSE) -> 0 | W16: 99.751717 | X16: 96.419983 | Y16: 0 | Z16: 58.495063 | AA16: 19.078958 | AB16: 18.991881 | AC16: 18.716766 | AD16: 3.4989524 | AE16: 3.6380044 | AF16: 3.8533996 | AG16: 1929.9911 | AH16: 1971.3238 | AI16: =VLOOKUP(B16,[7]all!$A$2:$I$247,6,FALSE) -> 68.43 | AJ16: =VLOOKUP(B16,[7]all!$A$2:$I$247,7,FALSE) -> 68.02 | AK16: =VLOOKUP(B16,[7]all!$A$2:$I$247,8,FALSE) -> 67.88
A17: Bangladesh | B17: BGD | C17: =VLOOKUP(B17,'[1]who-regions'!$B$1:$D$206,3,FALSE) -> SEAR | D17: =VLOOKUP(B17,'[2]Metadata - Countries'!$A$1:$B$266,2,FALSE) -> South Asia | E17: =VLOOKUP(B17,'[2]Metadata - Countries'!$A$1:$C$266,3,FALSE) -> Lower middle income | G17: 59.295191 | H17: =VLOOKUP(B17,[4]tas!$A$2:$H$247,5,FALSE) -> 25.82 | I17: =VLOOKUP(B17,[4]tas!$A$2:$H$247,6,FALSE) -> 25.91 | J17: =VLOOKUP(B17,[4]tas!$A$2:$H$247,7,FALSE) -> 25.93 | K17: 4.6013169e+11 | L17: 4.3741533e+11 | M17: 4.5011942e+11 | N17: =VLOOKUP(B17,[2]Data!$B$1:$G$267,4,FALSE) -> 2716.4859 | O17: =VLOOKUP(B17,[2]Data!$B$1:$G$267,5,FALSE) -> 2551.0177 | P17: =VLOOKUP(B17,[2]Data!$B$1:$G$267,6,FALSE) -> 2593.4161 | Q17: =VLOOKUP(B17,[5]Sheet1!$B$421:$K$628,10,FALSE) -> 0 | R17: =VLOOKUP(B17,[5]Sheet1!$B$213:$K$420,10,FALSE) -> 0 | S17: =VLOOKUP(B17,[5]Sheet1!$B$2:$K$207,10,FALSE) -> 0 | T17: =VLOOKUP(B17,[6]Sheet1!$B$421:$K$628,10,FALSE) -> 0 | U17: =VLOOKUP(B17,[6]Sheet1!$B$213:$K$420,10,FALSE) -> 0 | V17: =VLOOKUP(B17,[6]Sheet1!$B$2:$K$212,10,FALSE) -> 0 | W17: 0 | X17: 0 | Y17: 0 | Z17: 42.381376 | AA17: 28.77009 | AB17: 28.360882 | AC17: 27.988931 | AD17: 6.1351577 | AE17: 6.3205481 | AF17: 6.498463 | AG17: 1300.36 | AH17: 1319.1798 | AI17: =VLOOKUP(B17,[7]all!$A$2:$I$247,6,FALSE) -> 76.46 | AJ17: =VLOOKUP(B17,[7]all!$A$2:$I$247,7,FALSE) -> 76.29 | AK17: =VLOOKUP(B17,[7]all!$A$2:$I$247,8,FALSE) -> 76.37
A18: Barbados | B18: BRB | C18: =VLOOKUP(B18,'[1]who-regions'!$B$1:$D$206,3,FALSE) -> AMR | D18: =VLOOKUP(B18,'[2]Metadata - Countries'!$A$1:$B$266,2,FALSE) -> Latin America & Caribbean | E18: =VLOOKUP(B18,'[2]Metadata - Countries'!$A$1:$C$266,3,FALSE) -> High income | G18: 98.092462 | H18: =VLOOKUP(B18,[4]tas!$A$2:$H$247,5,FALSE) -> 26.73 | I18: =VLOOKUP(B18,[4]tas!$A$2:$H$247,6,FALSE) -> 26.77 | J18: =VLOOKUP(B18,[4]tas!$A$2:$H$247,7,FALSE) -> 26.78 | K18: 6257303500 | L18: 6720733200 | M18: 7165000000 | N18: =VLOOKUP(B18,[2]Data!$B$1:$G$267,4,FALSE) -> 24387.039 | O18: =VLOOKUP(B18,[2]Data!$B$1:$G$267,5,FALSE) -> 25583.879 | P18: =VLOOKUP(B18,[2]Data!$B$1:$G$267,6,FALSE) -> 26544.871 | Q18: =VLOOKUP(B18,[5]Sheet1!$B$421:$K$628,10,FALSE) -> 0 | R18: =VLOOKUP(B18,[5]Sheet1!$B$213:$K$420,10,FALSE) -> 0 | S18: =VLOOKUP(B18,[5]Sheet1!$B$2:$K$207,10,FALSE) -> 0 | T18: =VLOOKUP(B18,[6]Sheet1!$B$421:$K$628,10,FALSE) -> 0 | U18: =VLOOKUP(B18,[6]Sheet1!$B$213:$K$420,10,FALSE) -> 0 | V18: =VLOOKUP(B18,[6]Sheet1!$B$2:$K$212,10,FALSE) -> 0 | W18: 94.68705 | X18: 0 | Y18: 0 | Z18: 23.730966 | AA18: 17.725402 | AB18: 17.486789 | AC18: 17.241276 | AD18: 15.698786 | AE18: 16.093414 | AF18: 16.550223 | AG18: 656.55349 | AH18: 656.59535 | AI18: =VLOOKUP(B18,[7]all!$A$2:$I$247,6,FALSE) -> 80.89 | AJ18: =VLOOKUP(B18,[7]all!$A$2:$I$247,7,FALSE) -> 80.9 | AK18: =VLOOKUP(B18,[7]all!$A$2:$I$247,8,FALSE) -> 80.85
A19: Belarus | B19: BLR | C19: =VLOOKUP(B19,'[1]who-regions'!$B$1:$D$206,3,FALSE) -> EUR | D19: =VLOOKUP(B19,'[2]Metadata - Countries'!$A$1:$B$266,2,FALSE) -> Europe & Central Asia | E19: =VLOOKUP(B19,'[2]Metadata - Countries'!$A$1:$C$266,3,FALSE) -> Upper middle income | G19: 99.558664 | H19: =VLOOKUP(B19,[4]tas!$A$2:$H$247,5,FALSE) -> 8.1 | I19: =VLOOKUP(B19,[4]tas!$A$2:$H$247,6,FALSE) -> 7.84 | J19: =VLOOKUP(B19,[4]tas!$A$2:$H$247,7,FALSE) -> 7.76 | K19: 7.377518e+10 | L19: 7.247876e+10 | M19: 7.5961865e+10 | N19: =VLOOKUP(B19,[2]Data!$B$1:$G$267,4,FALSE) -> 7994.6481 | O19: =VLOOKUP(B19,[2]Data!$B$1:$G$267,5,FALSE) -> 7896.7539 | P19: =VLOOKUP(B19,[2]Data!$B$1:$G$267,6,FALSE) -> 8317.634 | Q19: =VLOOKUP(B19,[5]Sheet1!$B$421:$K$628,10,FALSE) -> 8.75 | R19: =VLOOKUP(B19,[5]Sheet1!$B$213:$K$420,10,FALSE) -> 9.82 | S19: =VLOOKUP(B19,[5]Sheet1!$B$2:$K$207,10,FALSE) -> 5.77 | T19: =VLOOKUP(B19,[6]Sheet1!$B$421:$K$628,10,FALSE) -> 75.97 | U19: =VLOOKUP(B19,[6]Sheet1!$B$213:$K$420,10,FALSE) -> 76.13 | V19: =VLOOKUP(B19,[6]Sheet1!$B$2:$K$212,10,FALSE) -> 39.93 | W19: 95.092247 | X19: 97.862228 | Y19: 0 | Z19: 14.60899 | AA19: 16.959853 | AB19: 16.675284 | AC19: 16.297229 | AD19: 16.506785 | AE19: 17.061975 | AF19: 17.666564 | AG19: 45.460717 | AH19: 45.217077 | AI19: =VLOOKUP(B19,[7]all!$A$2:$I$247,6,FALSE) -> 78 | AJ19: =VLOOKUP(B19,[7]all!$A$2:$I$247,7,FALSE) -> 78.06 | AK19: =VLOOKUP(B19,[7]all!$A$2:$I$247,8,FALSE) -> 78.23 | AL19: 4290
A20: Belgium | B20: BEL | C20: =VLOOKUP(B20,'[1]who-regions'!$B$1:$D$206,3,FALSE) -> EUR | D20: =VLOOKUP(B20,'[2]Metadata - Countries'!$A$1:$B$266,2,FALSE) -> Europe & Central Asia | E20: =VLOOKUP(B20,'[2]Metadata - Countries'!$A$1:$C$266,3,FALSE) -> High income | G20: 99.486217 | H20: =VLOOKUP(B20,[4]tas!$A$2:$H$247,5,FALSE) -> 10.78 | I20: =VLOOKUP(B20,[4]tas!$A$2:$H$247,6,FALSE) -> 10.6 | J20: =VLOOKUP(B20,[4]tas!$A$2:$H$247,7,FALSE) -> 10.65 | K20: 5.9361457e+11 | L20: 6.4465528e+11 | M20: 6.6456418e+11 | N20: =VLOOKUP(B20,[2]Data!$B$1:$G$267,4,FALSE) -> 50605.75 | O20: =VLOOKUP(B20,[2]Data!$B$1:$G$267,5,FALSE) -> 55291.475 | P20: =VLOOKUP(B20,[2]Data!$B$1:$G$267,6,FALSE) -> 56614.568 | Q20: =VLOOKUP(B20,[5]Sheet1!$B$421:$K$628,10,FALSE) -> 0 | R20: =VLOOKUP(B20,[5]Sheet1!$B$213:$K$420,10,FALSE) -> 0 | S20: =VLOOKUP(B20,[5]Sheet1!$B$2:$K$207,10,FALSE) -> 0 | T20: =VLOOKUP(B20,[6]Sheet1!$B$421:$K$628,10,FALSE) -> 57.3 | U20: =VLOOKUP(B20,[6]Sheet1!$B$213:$K$420,10,FALSE) -> 0 | V20: =VLOOKUP(B20,[6]Sheet1!$B$2:$K$212,10,FALSE) -> 0 | W20: 0 | X20: 0 | Y20: 0 | Z20: 11.216066 | AA20: 16.529679 | AB20: 16.290745 | AC20: 15.996127 | AD20: 19.767193 | AE20: 20.145275 | AF20: 20.558081 | AG20: 383.03306 | AH20: 386.54893 | AI20: =VLOOKUP(B20,[7]all!$A$2:$I$247,6,FALSE) -> 80.15 | AJ20: =VLOOKUP(B20,[7]all!$A$2:$I$247,7,FALSE) -> 80.3 | AK20: =VLOOKUP(B20,[7]all!$A$2:$I$247,8,FALSE) -> 80.08
A21: Belize | B21: BLZ | C21: =VLOOKUP(B21,'[1]who-regions'!$B$1:$D$206,3,FALSE) -> AMR | D21: =VLOOKUP(B21,'[2]Metadata - Countries'!$A$1:$B$266,2,FALSE) -> Latin America & Caribbean | E21: =VLOOKUP(B21,'[2]Metadata - Countries'!$A$1:$C$266,3,FALSE) -> Upper middle income | G21: 88.251078 | H21: =VLOOKUP(B21,[4]tas!$A$2:$H$247,5,FALSE) -> 26.2 | I21: =VLOOKUP(B21,[4]tas!$A$2:$H$247,6,FALSE) -> 26.29 | J21: =VLOOKUP(B21,[4]tas!$A$2:$H$247,7,FALSE) -> 26.29 | K21: 2846700000 | L21: 3066850000 | M21: 3.5157833e+09 | N21: =VLOOKUP(B21,[2]Data!$B$1:$G$267,4,FALSE) -> 7068.2173 | O21: =VLOOKUP(B21,[2]Data!$B$1:$G$267,5,FALSE) -> 7424.7582 | P21: =VLOOKUP(B21,[2]Data!$B$1:$G$267,6,FALSE) -> 7681.244 | Q21: =VLOOKUP(B21,[5]Sheet1!$B$421:$K$628,10,FALSE) -> 0 | R21: =VLOOKUP(B21,[5]Sheet1!$B$213:$K$420,10,FALSE) -> 0 | S21: =VLOOKUP(B21,[5]Sheet1!$B$2:$K$207,10,FALSE) -> 0 | T21: =VLOOKUP(B21,[6]Sheet1!$B$421:$K$628,10,FALSE) -> 0.8 | U21: =VLOOKUP(B21,[6]Sheet1!$B$213:$K$420,10,FALSE) -> 2.96 | V21: =VLOOKUP(B21,[6]Sheet1!$B$2:$K$212,10,FALSE) -> 1.62 | W21: 86.889328 | X21: 96.053169 | Y21: 0 | Z21: 28.651807 | AA21: 27.610849 | AB21: 26.992585 | AC21: 26.578416 | AD21: 4.7083303 | AE21: 4.8413363 | AF21: 5.0238388 | AG21: 17.655984 | AH21: 18.02306 | AI21: =VLOOKUP(B21,[7]all!$A$2:$I$247,6,FALSE) -> 80.78 | AJ21: =VLOOKUP(B21,[7]all!$A$2:$I$247,7,FALSE) -> 80.57 | AK21: =VLOOKUP(B21,[7]all!$A$2:$I$247,8,FALSE) -> 80.8
A22: Benin | B22: BEN | C22: =VLOOKUP(B22,'[1]who-regions'!$B$1:$D$206,3,FALSE) -> AFR | D22: =VLOOKUP(B22,'[2]Metadata - Countries'!$A$1:$B$266,2,FALSE) -> Sub-Saharan Africa | E22: =VLOOKUP(B22,'[2]Metadata - Countries'!$A$1:$C$266,3,FALSE) -> Lower middle income | G22: 19.493502 | H22: =VLOOKUP(B22,[4]tas!$A$2:$H$247,5,FALSE) -> 28.2 | I22: =VLOOKUP(B22,[4]tas!$A$2:$H$247,6,FALSE) -> 28.22 | J22: =VLOOKUP(B22,[4]tas!$A$2:$H$247,7,FALSE) -> 28.35 | K22: 1.7425405e+10 | L22: 1.9673291e+10 | M22: 2.1482644e+10 | N22: =VLOOKUP(B22,[2]Data!$B$1:$G$267,4,FALSE) -> 1266.4271 | O22: =VLOOKUP(B22,[2]Data!$B$1:$G$267,5,FALSE) -> 1394.1778 | P22: =VLOOKUP(B22,[2]Data!$B$1:$G$267,6,FALSE) -> 1485.3802 | Q22: =VLOOKUP(B22,[5]Sheet1!$B$421:$K$628,10,FALSE) -> 0 | R22: =VLOOKUP(B22,[5]Sheet1!$B$213:$K$420,10,FALSE) -> 0 | S22: =VLOOKUP(B22,[5]Sheet1!$B$2:$K$207,10,FALSE) -> 0 | T22: =VLOOKUP(B22,[6]Sheet1!$B$421:$K$628,10,FALSE) -> 0 | U22: =VLOOKUP(B22,[6]Sheet1!$B$213:$K$420,10,FALSE) -> 0 | V22: =VLOOKUP(B22,[6]Sheet1!$B$2:$K$212,10,FALSE) -> 0 | W22: 0 | X22: 0 | Y22: 0 | Z22: 51.047824 | AA22: 42.120631 | AB22: 41.836267 | AC22: 41.55249 | AD22: 3.0625312 | AE22: 3.0878813 | AF22: 3.118147 | AG22: 122.02466 | AH22: 125.1422 | AI22: =VLOOKUP(B22,[7]all!$A$2:$I$247,6,FALSE) -> 61.06 | AJ22: =VLOOKUP(B22,[7]all!$A$2:$I$247,7,FALSE) -> 61.23 | AK22: =VLOOKUP(B22,[7]all!$A$2:$I$247,8,FALSE) -> 61.22
A23: Bermuda | B23: BMU | C23: None | D23: =VLOOKUP(B23,'[2]Metadata - Countries'!$A$1:$B$266,2,FALSE) -> North America | E23: =VLOOKUP(B23,'[2]Metadata - Countries'!$A$1:$C$266,3,FALSE) -> High income | G23: 99.941653 | H23: =VLOOKUP(B23,[4]tas!$A$2:$H$247,5,FALSE) -> 22.26 | I23: =VLOOKUP(B23,[4]tas!$A$2:$H$247,6,FALSE) -> 22.31 | J23: =VLOOKUP(B23,[4]tas!$A$2:$H$247,7,FALSE) -> 22.31 | K23: 7874381000 | L23: 8579242000 | M23: 8980200000 | N23: =VLOOKUP(B23,[2]Data!$B$1:$G$267,4,FALSE) -> 121613.94 | O23: =VLOOKUP(B23,[2]Data!$B$1:$G$267,5,FALSE) -> 132604.44 | P23: =VLOOKUP(B23,[2]Data!$B$1:$G$267,6,FALSE) -> 142855.37 | Q23: =VLOOKUP(B23,[5]Sheet1!$B$421:$K$628,10,FALSE) -> 7.24 | R23: =VLOOKUP(B23,[5]Sheet1!$B$213:$K$420,10,FALSE) -> 0 | S23: =VLOOKUP(B23,[5]Sheet1!$B$2:$K$207,10,FALSE) -> 0 | T23: =VLOOKUP(B23,[6]Sheet1!$B$421:$K$628,10,FALSE) -> 0 | U23: =VLOOKUP(B23,[6]Sheet1!$B$213:$K$420,10,FALSE) -> 6.09 | V23: =VLOOKUP(B23,[6]Sheet1!$B$2:$K$212,10,FALSE) -> 7.06 | W23: 0 | X23: 0 | Y23: 0 | Z23: 7.3360005 | AA23: 14.126968 | AB23: 13.878327 | AC23: 13.606863 | AD23: 20.141779 | AE23: 20.911775 | AF23: 21.743906 | AG23: 1199.0556 | AH23: 1198.1111 | AI23: =VLOOKUP(B23,[7]all!$A$2:$I$247,6,FALSE) -> 75.89 | AJ23: =VLOOKUP(B23,[7]all!$A$2:$I$247,7,FALSE) -> 75.76 | AK23: =VLOOKUP(B23,[7]all!$A$2:$I$247,8,FALSE) -> 75.9
A24: Bhutan | B24: BTN | C24: =VLOOKUP(B24,'[1]who-regions'!$B$1:$D$206,3,FALSE) -> SEAR | D24: =VLOOKUP(B24,'[2]Metadata - Countries'!$A$1:$B$266,2,FALSE) -> South Asia | E24: =VLOOKUP(B24,'[2]Metadata - Countries'!$A$1:$C$266,3,FALSE) -> Lower middle income | G24: 77.940074 | H24: =VLOOKUP(B24,[4]tas!$A$2:$H$247,5,FALSE) -> 10.07 | I24: =VLOOKUP(B24,[4]tas!$A$2:$H$247,6,FALSE) -> 10.13 | J24: =VLOOKUP(B24,[4]tas!$A$2:$H$247,7,FALSE) -> 10.22 | K24: 2.8982277e+09 | L24: 3.0192539e+09 | M24: 0 | N24: =VLOOKUP(B24,[2]Data!$B$1:$G$267,4,FALSE) -> 3711.3277 | O24: =VLOOKUP(B24,[2]Data!$B$1:$G$267,5,FALSE) -> 3831.3254 | P24: =VLOOKUP(B24,[2]Data!$B$1:$G$267,6,FALSE) -> 0 | Q24: =VLOOKUP(B24,[5]Sheet1!$B$421:$K$628,10,FALSE) -> 0 | R24: =VLOOKUP(B24,[5]Sheet1!$B$213:$K$420,10,FALSE) -> 0 | S24: =VLOOKUP(B24,[5]Sheet1!$B$2:$K$207,10,FALSE) -> 0 | T24: =VLOOKUP(B24,[6]Sheet1!$B$421:$K$628,10,FALSE) -> 70.85 | U24: =VLOOKUP(B24,[6]Sheet1!$B$213:$K$420,10,FALSE) -> 78.71 | V24: =VLOOKUP(B24,[6]Sheet1!$B$2:$K$212,10,FALSE) -> 80.15 | W24: 0 | X24: 0 | Y24: 0 | Z24: 23.945658 | AA24: 22.038904 | AB24: 21.461498 | AC24: 20.909397 | AD24: 6.2457542 | AE24: 6.3686998 | AF24: 6.4942399 | AG24: 20.474934 | AH24: 20.61838 | AI24: =VLOOKUP(B24,[7]all!$A$2:$I$247,6,FALSE) -> 81.56 | AJ24: =VLOOKUP(B24,[7]all!$A$2:$I$247,7,FALSE) -> 81.56 | AK24: =VLOOKUP(B24,[7]all!$A$2:$I$247,8,FALSE) -> 81.66
A25: Bolivia | B25: BOL | C25: =VLOOKUP(B25,'[1]who-regions'!$B$1:$D$206,3,FALSE) -> AMR | D25: =VLOOKUP(B25,'[2]Metadata - Countries'!$A$1:$B$266,2,FALSE) -> Latin America & Caribbean | E25: =VLOOKUP(B25,'[2]Metadata - Countries'!$A$1:$C$266,3,FALSE) -> Lower middle income | G25: 68.612563 | H25: =VLOOKUP(B25,[4]tas!$A$2:$H$247,5,FALSE) -> 21.41 | I25: =VLOOKUP(B25,[4]tas!$A$2:$H$247,6,FALSE) -> 21.44 | J25: =VLOOKUP(B25,[4]tas!$A$2:$H$247,7,FALSE) -> 21.52 | K25: 4.4008283e+10 | L25: 4.5135398e+10 | M25: 4.9668297e+10 | N25: =VLOOKUP(B25,[2]Data!$B$1:$G$267,4,FALSE) -> 4219.4611 | O25: =VLOOKUP(B25,[2]Data!$B$1:$G$267,5,FALSE) -> 4274.7082 | P25: =VLOOKUP(B25,[2]Data!$B$1:$G$267,6,FALSE) -> 4421.1661 | Q25: =VLOOKUP(B25,[5]Sheet1!$B$421:$K$628,10,FALSE) -> 0 | R25: =VLOOKUP(B25,[5]Sheet1!$B$213:$K$420,10,FALSE) -> 0 | S25: =VLOOKUP(B25,[5]Sheet1!$B$2:$K$207,10,FALSE) -> 0 | T25: =VLOOKUP(B25,[6]Sheet1!$B$421:$K$628,10,FALSE) -> 50.66 | U25: =VLOOKUP(B25,[6]Sheet1!$B$213:$K$420,10,FALSE) -> 55.15 | V25: =VLOOKUP(B25,[6]Sheet1!$B$2:$K$212,10,FALSE) -> 52.14 | W25: 96.872269 | X25: 0 | Y25: 0 | Z25: 22.879459 | AA25: 30.498526 | AB25: 30.1424 | AC25: 29.786564 | AD25: 5.4790806 | AE25: 5.5504667 | AF25: 5.6414745 | AG25: 11.148485 | AH25: 11.302648 | AI25: =VLOOKUP(B25,[7]all!$A$2:$I$247,6,FALSE) -> 66.03 | AJ25: =VLOOKUP(B25,[7]all!$A$2:$I$247,7,FALSE) -> 65.98 | AK25: =VLOOKUP(B25,[7]all!$A$2:$I$247,8,FALSE) -> 65.6
A26: Bosnia and Herzegovina | B26: BIH | C26: =VLOOKUP(B26,'[1]who-regions'!$B$1:$D$206,3,FALSE) -> EUR | D26: =VLOOKUP(B26,'[2]Metadata - Countries'!$A$1:$B$266,2,FALSE) -> Europe & Central Asia | E26: =VLOOKUP(B26,'[2]Metadata - Countries'!$A$1:$C$266,3,FALSE) -> Upper middle income | G26: 0 | H26: =VLOOKUP(B26,[4]tas!$A$2:$H$247,5,FALSE) -> 11 | I26: =VLOOKUP(B26,[4]tas!$A$2:$H$247,6,FALSE) -> 11.02 | J26: =VLOOKUP(B26,[4]tas!$A$2:$H$247,7,FALSE) -> 11.03 | K26: 2.4534664e+10 | L26: 2.7592361e+10 | M26: 2.8343394e+10 | N26: =VLOOKUP(B26,[2]Data!$B$1:$G$267,4,FALSE) -> 7655.5942 | O26: =VLOOKUP(B26,[2]Data!$B$1:$G$267,5,FALSE) -> 8663.0233 | P26: =VLOOKUP(B26,[2]Data!$B$1:$G$267,6,FALSE) -> 9358.7877 | Q26: =VLOOKUP(B26,[5]Sheet1!$B$421:$K$628,10,FALSE) -> 0 | R26: =VLOOKUP(B26,[5]Sheet1!$B$213:$K$420,10,FALSE) -> 0 | S26: =VLOOKUP(B26,[5]Sheet1!$B$2:$K$207,10,FALSE) -> 0 | T26: =VLOOKUP(B26,[6]Sheet1!$B$421:$K$628,10,FALSE) -> 4.8 | U26: =VLOOKUP(B26,[6]Sheet1!$B$213:$K$420,10,FALSE) -> 6.5 | V26: =VLOOKUP(B26,[6]Sheet1!$B$2:$K$212,10,FALSE) -> 0 | W26: 95.724907 | X26: 0 | Y26: 0 | Z26: 26.601953 | AA26: 13.376505 | AB26: 13.219917 | AC26: 13.037817 | AD26: 21.103269 | AE26: 21.642424 | AF26: 22.230239 | AG26: 62.593789 | AH26: 62.208457 | AI26: =VLOOKUP(B26,[7]all!$A$2:$I$247,6,FALSE) -> 74.62 | AJ26: =VLOOKUP(B26,[7]all!$A$2:$I$247,7,FALSE) -> 74.69 | AK26: =VLOOKUP(B26,[7]all!$A$2:$I$247,8,FALSE) -> 74.81
A27: Botswana | B27: BWA | C27: =VLOOKUP(B27,'[1]who-regions'!$B$1:$D$206,3,FALSE) -> AFR | D27: =VLOOKUP(B27,'[2]Metadata - Countries'!$A$1:$B$266,2,FALSE) -> Sub-Saharan Africa | E27: =VLOOKUP(B27,'[2]Metadata - Countries'!$A$1:$C$266,3,FALSE) -> Upper middle income | G27: 80.550817 | H27: =VLOOKUP(B27,[4]tas!$A$2:$H$247,5,FALSE) -> 23.05 | I27: =VLOOKUP(B27,[4]tas!$A$2:$H$247,6,FALSE) -> 23.08 | J27: =VLOOKUP(B27,[4]tas!$A$2:$H$247,7,FALSE) -> 23.02 | K27: 2.0321151e+10 | L27: 1.9411267e+10 | M27: 1.9400775e+10 | N27: =VLOOKUP(B27,[2]Data!$B$1:$G$267,4,FALSE) -> 8328.7091 | O27: =VLOOKUP(B27,[2]Data!$B$1:$G$267,5,FALSE) -> 7826.3538 | P27: =VLOOKUP(B27,[2]Data!$B$1:$G$267,6,FALSE) -> 7695.7532 | Q27: =VLOOKUP(B27,[5]Sheet1!$B$421:$K$628,10,FALSE) -> 0 | R27: =VLOOKUP(B27,[5]Sheet1!$B$213:$K$420,10,FALSE) -> 0 | S27: =VLOOKUP(B27,[5]Sheet1!$B$2:$K$207,10,FALSE) -> 0 | T27: =VLOOKUP(B27,[6]Sheet1!$B$421:$K$628,10,FALSE) -> 0 | U27: =VLOOKUP(B27,[6]Sheet1!$B$213:$K$420,10,FALSE) -> 0 | V27: =VLOOKUP(B27,[6]Sheet1!$B$2:$K$212,10,FALSE) -> 0 | W27: 0 | X27: 0 | Y27: 0 | Z27: 18.905755 | AA27: 32.423225 | AB27: 32.281253 | AC27: 32.129645 | AD27: 3.880152 | AE27: 3.9696691 | AF27: 4.0358941 | AG27: 4.3052106 | AH27: 4.376412 | AI27: =VLOOKUP(B27,[7]all!$A$2:$I$247,6,FALSE) -> 44.33 | AJ27: =VLOOKUP(B27,[7]all!$A$2:$I$247,7,FALSE) -> 44.16 | AK27: =VLOOKUP(B27,[7]all!$A$2:$I$247,8,FALSE) -> 44.71
A28: Brazil | B28: BRA | C28: =VLOOKUP(B28,'[1]who-regions'!$B$1:$D$206,3,FALSE) -> AMR | D28: =VLOOKUP(B28,'[2]Metadata - Countries'!$A$1:$B$266,2,FALSE) -> Latin America & Caribbean | E28: =VLOOKUP(B28,'[2]Metadata - Countries'!$A$1:$C$266,3,FALSE) -> Upper middle income | G28: 90.883499 | H28: =VLOOKUP(B28,[4]tas!$A$2:$H$247,5,FALSE) -> 26.04 | I28: =VLOOKUP(B28,[4]tas!$A$2:$H$247,6,FALSE) -> 26.06 | J28: =VLOOKUP(B28,[4]tas!$A$2:$H$247,7,FALSE) -> 26.1 | K28: 1.9519239e+12 | L28: 2.1911318e+12 | M28: 2.1794121e+12 | N28: =VLOOKUP(B28,[2]Data!$B$1:$G$267,4,FALSE) -> 9281.3328 | O28: =VLOOKUP(B28,[2]Data!$B$1:$G$267,5,FALSE) -> 10377.59 | P28: =VLOOKUP(B28,[2]Data!$B$1:$G$267,6,FALSE) -> 10310.549 | Q28: =VLOOKUP(B28,[5]Sheet1!$B$421:$K$628,10,FALSE) -> 0 | R28: =VLOOKUP(B28,[5]Sheet1!$B$213:$K$420,10,FALSE) -> 0 | S28: =VLOOKUP(B28,[5]Sheet1!$B$2:$K$207,10,FALSE) -> 0 | T28: =VLOOKUP(B28,[6]Sheet1!$B$421:$K$628,10,FALSE) -> 70.24 | U28: =VLOOKUP(B28,[6]Sheet1!$B$213:$K$420,10,FALSE) -> 63.3 | V28: =VLOOKUP(B28,[6]Sheet1!$B$2:$K$212,10,FALSE) -> 45.4 | W28: 0 | X28: 0 | Y28: 0 | Z28: 12.179325 | AA28: 20.202477 | AB28: 19.935952 | AC28: 19.66514 | AD28: 10.251785 | AE28: 10.633631 | AF28: 11.049184 | AG28: 25.161868 | AH28: 25.261688 | AI28: =VLOOKUP(B28,[7]all!$A$2:$I$247,6,FALSE) -> 72.82 | AJ28: =VLOOKUP(B28,[7]all!$A$2:$I$247,7,FALSE) -> 72.67 | AK28: =VLOOKUP(B28,[7]all!$A$2:$I$247,8,FALSE) -> 72.76
A29: British Virgin Islands | B29: VGB | C29: None | D29: =VLOOKUP(B29,'[2]Metadata - Countries'!$A$1:$B$266,2,FALSE) -> Latin America & Caribbean | E29: =VLOOKUP(B29,'[2]Metadata - Countries'!$A$1:$C$266,3,FALSE) -> High income | G29: 0 | H29: =VLOOKUP(B29,[4]tas!$A$2:$H$247,5,FALSE) -> 26.57 | I29: =VLOOKUP(B29,[4]tas!$A$2:$H$247,6,FALSE) -> 26.58 | J29: =VLOOKUP(B29,[4]tas!$A$2:$H$247,7,FALSE) -> 26.61 | K29: 0 | L29: 0 | M29: 0 | N29: =VLOOKUP(B29,[2]Data!$B$1:$G$267,4,FALSE) -> 0 | O29: =VLOOKUP(B29,[2]Data!$B$1:$G$267,5,FALSE) -> 0 | P29: =VLOOKUP(B29,[2]Data!$B$1:$G$267,6,FALSE) -> 0 | Q29: =VLOOKUP(B29,[5]Sheet1!$B$421:$K$628,10,FALSE) -> 0 | R29: =VLOOKUP(B29,[5]Sheet1!$B$213:$K$420,10,FALSE) -> 0 | S29: =VLOOKUP(B29,[5]Sheet1!$B$2:$K$207,10,FALSE) -> 0 | T29: =VLOOKUP(B29,[6]Sheet1!$B$421:$K$628,10,FALSE) -> 0 | U29: =VLOOKUP(B29,[6]Sheet1!$B$213:$K$420,10,FALSE) -> 0 | V29: =VLOOKUP(B29,[6]Sheet1!$B$2:$K$212,10,FALSE) -> 0 | W29: 0 | X29: 6.9237499 | Y29: 0 | Z29: 0 | AA29: 15.888985 | AB29: 15.139156 | AC29: 14.491652 | AD29: 8.8572249 | AE29: 9.2022573 | AF29: 9.6235211 | AG29: 255.46 | AH29: 259.9 | AI29: =VLOOKUP(B29,[7]all!$A$2:$I$247,6,FALSE) -> 80.09 | AJ29: =VLOOKUP(B29,[7]all!$A$2:$I$247,7,FALSE) -> 79.99 | AK29: =VLOOKUP(B29,[7]all!$A$2:$I$247,8,FALSE) -> 79.98
A30: Brunei Darussalam | B30: BRN | C30: =VLOOKUP(B30,'[1]who-regions'!$B$1:$D$206,3,FALSE) -> WPR | D30: =VLOOKUP(B30,'[2]Metadata - Countries'!$A$1:$B$266,2,FALSE) -> East Asia & Pacific | E30: =VLOOKUP(B30,'[2]Metadata - Countries'!$A$1:$C$266,3,FALSE) -> High income | G30: 99.480825 | H30: =VLOOKUP(B30,[4]tas!$A$2:$H$247,5,FALSE) -> 27.07 | I30: =VLOOKUP(B30,[4]tas!$A$2:$H$247,6,FALSE) -> 27.11 | J30: =VLOOKUP(B30,[4]tas!$A$2:$H$247,7,FALSE) -> 27.14 | K30: 1.6681536e+10 | L30: 1.5095085e+10 | M30: 1.5463134e+10 | N30: =VLOOKUP(B30,[2]Data!$B$1:$G$267,4,FALSE) -> 36632.928 | O30: =VLOOKUP(B30,[2]Data!$B$1:$G$267,5,FALSE) -> 32890.549 | P30: =VLOOKUP(B30,[2]Data!$B$1:$G$267,6,FALSE) -> 33153.474 | Q30: =VLOOKUP(B30,[5]Sheet1!$B$421:$K$628,10,FALSE) -> 0 | R30: =VLOOKUP(B30,[5]Sheet1!$B$213:$K$420,10,FALSE) -> 0 | S30: =VLOOKUP(B30,[5]Sheet1!$B$2:$K$207,10,FALSE) -> 0 | T30: =VLOOKUP(B30,[6]Sheet1!$B$421:$K$628,10,FALSE) -> 0 | U30: =VLOOKUP(B30,[6]Sheet1!$B$213:$K$420,10,FALSE) -> 0 | V30: =VLOOKUP(B30,[6]Sheet1!$B$2:$K$212,10,FALSE) -> 0 | W30: 0 | X30: 0 | Y30: 0 | Z30: 7.597265 | AA30: 21.181809 | AB30: 21.024363 | AC30: 20.82527 | AD30: 6.2017768 | AE30: 6.5110791 | AF30: 6.867846 | AG30: 86.40797 | AH30: 87.087097 | AI30: =VLOOKUP(B30,[7]all!$A$2:$I$247,6,FALSE) -> 83.43 | AJ30: =VLOOKUP(B30,[7]all!$A$2:$I$247,7,FALSE) -> 83.42 | AK30: =VLOOKUP(B30,[7]all!$A$2:$I$247,8,FALSE) -> 83.34
A31: Bulgaria | B31: BGR | C31: =VLOOKUP(B31,'[1]who-regions'!$B$1:$D$206,3,FALSE) -> EUR | D31: =VLOOKUP(B31,'[2]Metadata - Countries'!$A$1:$B$266,2,FALSE) -> Europe & Central Asia | E31: =VLOOKUP(B31,'[2]Metadata - Countries'!$A$1:$C$266,3,FALSE) -> High income | G31: 86.055863 | H31: =VLOOKUP(B31,[4]tas!$A$2:$H$247,5,FALSE) -> 12.38 | I31: =VLOOKUP(B31,[4]tas!$A$2:$H$247,6,FALSE) -> 12.38 | J31: =VLOOKUP(B31,[4]tas!$A$2:$H$247,7,FALSE) -> 12.41 | K31: 9.0509237e+10 | L31: 1.0239684e+11 | M31: 1.1221195e+11 | N31: =VLOOKUP(B31,[2]Data!$B$1:$G$267,4,FALSE) -> 13999.195 | O31: =VLOOKUP(B31,[2]Data!$B$1:$G$267,5,FALSE) -> 15853.209 | P31: =VLOOKUP(B31,[2]Data!$B$1:$G$267,6,FALSE) -> 17596.017 | Q31: =VLOOKUP(B31,[5]Sheet1!$B$421:$K$628,10,FALSE) -> 0 | R31: =VLOOKUP(B31,[5]Sheet1!$B$213:$K$420,10,FALSE) -> 0 | S31: =VLOOKUP(B31,[5]Sheet1!$B$2:$K$207,10,FALSE) -> 0 | T31: =VLOOKUP(B31,[6]Sheet1!$B$421:$K$628,10,FALSE) -> 0 | U31: =VLOOKUP(B31,[6]Sheet1!$B$213:$K$420,10,FALSE) -> 18.94 | V31: =VLOOKUP(B31,[6]Sheet1!$B$2:$K$212,10,FALSE) -> 21.5 | W31: 98.967499 | X31: 0 | Y31: 0 | Z31: 17.147424 | AA31: 14.539229 | AB31: 14.538201 | AC31: 14.474461 | AD31: 21.697297 | AE31: 21.832438 | AF31: 22.030336 | AG31: 59.553215 | AH31: 59.382793 | AI31: =VLOOKUP(B31,[7]all!$A$2:$I$247,6,FALSE) -> 72.19 | AJ31: =VLOOKUP(B31,[7]all!$A$2:$I$247,7,FALSE) -> 72.49 | AK31: =VLOOKUP(B31,[7]all!$A$2:$I$247,8,FALSE) -> 72.8 | AL31: 6397
A32: Burkina Faso | B32: BFA | C32: =VLOOKUP(B32,'[1]who-regions'!$B$1:$D$206,3,FALSE) -> AFR | D32: =VLOOKUP(B32,'[2]Metadata - Countries'!$A$1:$B$266,2,FALSE) -> Sub-Saharan Africa | E32: =VLOOKUP(B32,'[2]Metadata - Countries'!$A$1:$C$266,3,FALSE) -> Low income | G32: 24.756494 | H32: =VLOOKUP(B32,[4]tas!$A$2:$H$247,5,FALSE) -> 29.17 | I32: =VLOOKUP(B32,[4]tas!$A$2:$H$247,6,FALSE) -> 29.13 | J32: =VLOOKUP(B32,[4]tas!$A$2:$H$247,7,FALSE) -> 29.31 | K32: 1.8820219e+10 | L32: 2.0324618e+10 | M32: 2.3250215e+10 | N32: =VLOOKUP(B32,[2]Data!$B$1:$G$267,4,FALSE) -> 827.33084 | O32: =VLOOKUP(B32,[2]Data!$B$1:$G$267,5,FALSE) -> 873.48259 | P32: =VLOOKUP(B32,[2]Data!$B$1:$G$267,6,FALSE) -> 981.99265 | Q32: =VLOOKUP(B32,[5]Sheet1!$B$421:$K$628,10,FALSE) -> 0 | R32: =VLOOKUP(B32,[5]Sheet1!$B$213:$K$420,10,FALSE) -> 0 | S32: =VLOOKUP(B32,[5]Sheet1!$B$2:$K$207,10,FALSE) -> 0 | T32: =VLOOKUP(B32,[6]Sheet1!$B$421:$K$628,10,FALSE) -> 0 | U32: =VLOOKUP(B32,[6]Sheet1!$B$213:$K$420,10,FALSE) -> 0 | V32: =VLOOKUP(B32,[6]Sheet1!$B$2:$K$212,10,FALSE) -> 0 | W32: 31.028971 | X32: 0 | Y32: 0 | Z32: 58.470676 | AA32: 42.968317 | AB32: 42.401251 | AC32: 41.80203 | AD32: 2.5946555 | AE32: 2.620713 | AF32: 2.6517721 | AG32: 82.269876 | AH32: 84.158538 | AI32: =VLOOKUP(B32,[7]all!$A$2:$I$247,6,FALSE) -> 47.58 | AJ32: =VLOOKUP(B32,[7]all!$A$2:$I$247,7,FALSE) -> 47.64 | AK32: =VLOOKUP(B32,[7]all!$A$2:$I$247,8,FALSE) -> 47.65
A33: Burundi | B33: BDI | C33: =VLOOKUP(B33,'[1]who-regions'!$B$1:$D$206,3,FALSE) -> AFR | D33: =VLOOKUP(B33,'[2]Metadata - Countries'!$A$1:$B$266,2,FALSE) -> Sub-Saharan Africa | E33: =VLOOKUP(B33,'[2]Metadata - Countries'!$A$1:$C$266,3,FALSE) -> Low income | G33: 45.690685 | H33: =VLOOKUP(B33,[4]tas!$A$2:$H$247,5,FALSE) -> 21.1 | I33: =VLOOKUP(B33,[4]tas!$A$2:$H$247,6,FALSE) -> 21.11 | J33: =VLOOKUP(B33,[4]tas!$A$2:$H$247,7,FALSE) -> 21.21 | K33: 3.3387228e+09 | L33: 2.6293916e+09 | M33: 2.1623788e+09 | N33: =VLOOKUP(B33,[2]Data!$B$1:$G$267,4,FALSE) -> 302.99251 | O33: =VLOOKUP(B33,[2]Data!$B$1:$G$267,5,FALSE) -> 250.62725 | P33: =VLOOKUP(B33,[2]Data!$B$1:$G$267,6,FALSE) -> 219.42483 | Q33: =VLOOKUP(B33,[5]Sheet1!$B$421:$K$628,10,FALSE) -> 0 | R33: =VLOOKUP(B33,[5]Sheet1!$B$213:$K$420,10,FALSE) -> 0 | S33: =VLOOKUP(B33,[5]Sheet1!$B$2:$K$207,10,FALSE) -> 0 | T33: =VLOOKUP(B33,[6]Sheet1!$B$421:$K$628,10,FALSE) -> 0 | U33: =VLOOKUP(B33,[6]Sheet1!$B$213:$K$420,10,FALSE) -> 0 | V33: =VLOOKUP(B33,[6]Sheet1!$B$2:$K$212,10,FALSE) -> 0 | W33: 0 | X33: 0 | Y33: 0 | Z33: 29.654135 | AA33: 45.988891 | AB33: 45.364742 | AC33: 44.698901 | AD33: 2.48585 | AE33: 2.5102945 | AF33: 2.5318047 | AG33: 518.73431 | AH33: 533.07827 | AI33: =VLOOKUP(B33,[7]all!$A$2:$I$247,6,FALSE) -> 69.13 | AJ33: =VLOOKUP(B33,[7]all!$A$2:$I$247,7,FALSE) -> 69.08 | AK33: =VLOOKUP(B33,[7]all!$A$2:$I$247,8,FALSE) -> 68.84
A34: Cabo Verde | B34: CPV | C34: =VLOOKUP(B34,'[1]who-regions'!$B$1:$D$206,3,FALSE) -> AFR | D34: =VLOOKUP(B34,'[2]Metadata - Countries'!$A$1:$B$266,2,FALSE) -> Sub-Saharan Africa | E34: =VLOOKUP(B34,'[2]Metadata - Countries'!$A$1:$C$266,3,FALSE) -> Upper middle income | G34: 83.045303 | H34: =VLOOKUP(B34,[4]tas!$A$2:$H$247,5,FALSE) -> 23.71 | I34: =VLOOKUP(B34,[4]tas!$A$2:$H$247,6,FALSE) -> 23.64 | J34: =VLOOKUP(B34,[4]tas!$A$2:$H$247,7,FALSE) -> 23.68 | K34: 2.2470033e+09 | L34: 2.5392034e+09 | M34: 2.767599e+09 | N34: =VLOOKUP(B34,[2]Data!$B$1:$G$267,4,FALSE) -> 4323.3136 | O34: =VLOOKUP(B34,[2]Data!$B$1:$G$267,5,FALSE) -> 4794.9012 | P34: =VLOOKUP(B34,[2]Data!$B$1:$G$267,6,FALSE) -> 5192.4816 | Q34: =VLOOKUP(B34,[5]Sheet1!$B$421:$K$628,10,FALSE) -> 0 | R34: =VLOOKUP(B34,[5]Sheet1!$B$213:$K$420,10,FALSE) -> 0 | S34: =VLOOKUP(B34,[5]Sheet1!$B$2:$K$207,10,FALSE) -> 0 | T34: =VLOOKUP(B34,[6]Sheet1!$B$421:$K$628,10,FALSE) -> 0 | U34: =VLOOKUP(B34,[6]Sheet1!$B$213:$K$420,10,FALSE) -> 0 | V34: =VLOOKUP(B34,[6]Sheet1!$B$2:$K$212,10,FALSE) -> 0 | W34: 0 | X34: 0 | Y34: 0 | Z34: 42.322522 | AA34: 27.174593 | AB34: 26.370851 | AC34: 25.547319 | AD34: 6.3287291 | AE34: 6.579455 | AF34: 6.8581782 | AG34: 128.96799 | AH34: 129.61067 | AI34: =VLOOKUP(B34,[7]all!$A$2:$I$247,6,FALSE) -> 78.58 | AJ34: =VLOOKUP(B34,[7]all!$A$2:$I$247,7,FALSE) -> 78.66 | AK34: =VLOOKUP(B34,[7]all!$A$2:$I$247,8,FALSE) -> 78.59
A35: Cambodia | B35: KHM | C35: =VLOOKUP(B35,'[1]who-regions'!$B$1:$D$206,3,FALSE) -> WPR | D35: =VLOOKUP(B35,'[2]Metadata - Countries'!$A$1:$B$266,2,FALSE) -> East Asia & Pacific | E35: =VLOOKUP(B35,'[2]Metadata - Countries'!$A$1:$C$266,3,FALSE) -> Lower middle income | G35: 76.719418 | H35: =VLOOKUP(B35,[4]tas!$A$2:$H$247,5,FALSE) -> 28.19 | I35: =VLOOKUP(B35,[4]tas!$A$2:$H$247,6,FALSE) -> 28.22 | J35: =VLOOKUP(B35,[4]tas!$A$2:$H$247,7,FALSE) -> 28.21 | K35: 3.9994533e+10 | L35: 4.2335647e+10 | M35: 4.6352647e+10 | N35: =VLOOKUP(B35,[2]Data!$B$1:$G$267,4,FALSE) -> 2325.0305 | O35: =VLOOKUP(B35,[2]Data!$B$1:$G$267,5,FALSE) -> 2429.7485 | P35: =VLOOKUP(B35,[2]Data!$B$1:$G$267,6,FALSE) -> 2627.8797 | Q35: =VLOOKUP(B35,[5]Sheet1!$B$421:$K$628,10,FALSE) -> 0 | R35: =VLOOKUP(B35,[5]Sheet1!$B$213:$K$420,10,FALSE) -> 0 | S35: =VLOOKUP(B35,[5]Sheet1!$B$2:$K$207,10,FALSE) -> 0 | T35: =VLOOKUP(B35,[6]Sheet1!$B$421:$K$628,10,FALSE) -> 0 | U35: =VLOOKUP(B35,[6]Sheet1!$B$213:$K$420,10,FALSE) -> 0 | V35: =VLOOKUP(B35,[6]Sheet1!$B$2:$K$212,10,FALSE) -> 0 | W35: 0 | X35: 0 | Y35: 0 | Z35: 24.143602 | AA35: 30.454416 | AB35: 30.110557 | AC35: 29.793146 | AD35: 5.7669541 | AE35: 5.9611864 | AF35: 6.1637043 | AG35: 97.44915 | AH35: 98.707682 | AI35: =VLOOKUP(B35,[7]all!$A$2:$I$247,6,FALSE) -> 72.33 | AJ35: =VLOOKUP(B35,[7]all!$A$2:$I$247,7,FALSE) -> 72.38 | AK35: =VLOOKUP(B35,[7]all!$A$2:$I$247,8,FALSE) -> 72.43 | AL35: 13934
A36: Cameroon | B36: CMR | C36: =VLOOKUP(B36,'[1]who-regions'!$B$1:$D$206,3,FALSE) -> AFR | D36: =VLOOKUP(B36,'[2]Metadata - Countries'!$A$1:$B$266,2,FALSE) -> Sub-Saharan Africa | E36: =VLOOKUP(B36,'[2]Metadata - Countries'!$A$1:$C$266,3,FALSE) -> Lower middle income | G36: 43.119165 | H36: =VLOOKUP(B36,[4]tas!$A$2:$H$247,5,FALSE) -> 25.43 | I36: =VLOOKUP(B36,[4]tas!$A$2:$H$247,6,FALSE) -> 25.44 | J36: =VLOOKUP(B36,[4]tas!$A$2:$H$247,7,FALSE) -> 25.51 | K36: 4.4347206e+10 | L36: 4.9279411e+10 | M36: 5.1326765e+10 | N36: =VLOOKUP(B36,[2]Data!$B$1:$G$267,4,FALSE) -> 1604.8773 | O36: =VLOOKUP(B36,[2]Data!$B$1:$G$267,5,FALSE) -> 1720.4751 | P36: =VLOOKUP(B36,[2]Data!$B$1:$G$267,6,FALSE) -> 1830.0083 | Q36: =VLOOKUP(B36,[5]Sheet1!$B$421:$K$628,10,FALSE) -> 0 | R36: =VLOOKUP(B36,[5]Sheet1!$B$213:$K$420,10,FALSE) -> 0 | S36: =VLOOKUP(B36,[5]Sheet1!$B$2:$K$207,10,FALSE) -> 0 | T36: =VLOOKUP(B36,[6]Sheet1!$B$421:$K$628,10,FALSE) -> 0 | U36: =VLOOKUP(B36,[6]Sheet1!$B$213:$K$420,10,FALSE) -> 0 | V36: =VLOOKUP(B36,[6]Sheet1!$B$2:$K$212,10,FALSE) -> 0 | W36: 65.963402 | X36: 61.849499 | Y36: 0 | Z36: 39.812625 | AA36: 42.058201 | AB36: 41.760555 | AC36: 41.442227 | AD36: 2.763172 | AE36: 2.7748394 | AF36: 2.7947987 | AG36: 58.456075 | AH36: 60.021339 | AI36: =VLOOKUP(B36,[7]all!$A$2:$I$247,6,FALSE) -> 69.94 | AJ36: =VLOOKUP(B36,[7]all!$A$2:$I$247,7,FALSE) -> 69.87 | AK36: =VLOOKUP(B36,[7]all!$A$2:$I$247,8,FALSE) -> 69.94
A37: Canada | B37: CAN | C37: =VLOOKUP(B37,'[1]who-regions'!$B$1:$D$206,3,FALSE) -> AMR | D37: =VLOOKUP(B37,'[2]Metadata - Countries'!$A$1:$B$266,2,FALSE) -> North America | E37: =VLOOKUP(B37,'[2]Metadata - Countries'!$A$1:$C$266,3,FALSE) -> High income | G37: 98.588358 | H37: =VLOOKUP(B37,[4]tas!$A$2:$H$247,5,FALSE) -> -2.41 | I37: =VLOOKUP(B37,[4]tas!$A$2:$H$247,6,FALSE) -> -2.32 | J37: =VLOOKUP(B37,[4]tas!$A$2:$H$247,7,FALSE) -> -2.19 | K37: 2.1904111e+12 | L37: 2.1733397e+12 | M37: 2.2412532e+12 | N37: =VLOOKUP(B37,[2]Data!$B$1:$G$267,4,FALSE) -> 56256.801 | O37: =VLOOKUP(B37,[2]Data!$B$1:$G$267,5,FALSE) -> 54220.329 | P37: =VLOOKUP(B37,[2]Data!$B$1:$G$267,6,FALSE) -> 54340.348 | Q37: =VLOOKUP(B37,[5]Sheet1!$B$421:$K$628,10,FALSE) -> 0 | R37: =VLOOKUP(B37,[5]Sheet1!$B$213:$K$420,10,FALSE) -> 0 | S37: =VLOOKUP(B37,[5]Sheet1!$B$2:$K$207,10,FALSE) -> 0 | T37: =VLOOKUP(B37,[6]Sheet1!$B$421:$K$628,10,FALSE) -> 71 | U37: =VLOOKUP(B37,[6]Sheet1!$B$213:$K$420,10,FALSE) -> 73.7 | V37: =VLOOKUP(B37,[6]Sheet1!$B$2:$K$212,10,FALSE) -> 73.7 | W37: 0 | X37: 0 | Y37: 0 | Z37: 6.5656699 | AA37: 15.547908 | AB37: 15.304543 | AC37: 15.111321 | AD37: 18.940747 | AE37: 19.358119 | AF37: 19.799591 | AG37: 4.4302268 | AH37: 4.5607978 | AI37: =VLOOKUP(B37,[7]all!$A$2:$I$247,6,FALSE) -> 72.52 | AJ37: =VLOOKUP(B37,[7]all!$A$2:$I$247,7,FALSE) -> 72.46 | AK37: =VLOOKUP(B37,[7]all!$A$2:$I$247,8,FALSE) -> 72.4 | AL37: 258830.5
A38: Cayman Islands | B38: CYM | C38: =VLOOKUP(B38,'[1]who-regions'!$B$1:$D$206,3,FALSE) -> AMR | D38: =VLOOKUP(B38,'[2]Metadata - Countries'!$A$1:$B$266,2,FALSE) -> Latin America & Caribbean | E38: =VLOOKUP(B38,'[2]Metadata - Countries'!$A$1:$C$266,3,FALSE) -> High income | G38: 83.266288 | H38: =VLOOKUP(B38,[4]tas!$A$2:$H$247,5,FALSE) -> 27.15 | I38: =VLOOKUP(B38,[4]tas!$A$2:$H$247,6,FALSE) -> 27.15 | J38: =VLOOKUP(B38,[4]tas!$A$2:$H$247,7,FALSE) -> 27.18 | K38: 6.600844e+09 | L38: 7.1394286e+09 | M38: 0 | N38: =VLOOKUP(B38,[2]Data!$B$1:$G$267,4,FALSE) -> 93030.705 | O38: =VLOOKUP(B38,[2]Data!$B$1:$G$267,5,FALSE) -> 99143.518 | P38: =VLOOKUP(B38,[2]Data!$B$1:$G$267,6,FALSE) -> 0 | Q38: =VLOOKUP(B38,[5]Sheet1!$B$421:$K$628,10,FALSE) -> 0 | R38: =VLOOKUP(B38,[5]Sheet1!$B$213:$K$420,10,FALSE) -> 0 | S38: =VLOOKUP(B38,[5]Sheet1!$B$2:$K$207,10,FALSE) -> 0 | T38: =VLOOKUP(B38,[6]Sheet1!$B$421:$K$628,10,FALSE) -> 0 | U38: =VLOOKUP(B38,[6]Sheet1!$B$213:$K$420,10,FALSE) -> 0 | V38: =VLOOKUP(B38,[6]Sheet1!$B$2:$K$212,10,FALSE) -> 0 | W38: 0 | X38: 85.285263 | Y38: 0 | Z38: 0 | AA38: 16.355294 | AB38: 16.294258 | AC38: 16.187758 | AD38: 8.1378376 | AE38: 8.5414442 | AF38: 8.9977504 | AG38: 298.29583 | AH38: 304.325 | AI38: =VLOOKUP(B38,[7]all!$A$2:$I$247,6,FALSE) -> 79.27 | AJ38: =VLOOKUP(B38,[7]all!$A$2:$I$247,7,FALSE) -> 79.38 | AK38: =VLOOKUP(B38,[7]all!$A$2:$I$247,8,FALSE) -> 79.39
A39: Central African Republic | B39: CAF | C39: =VLOOKUP(B39,'[1]who-regions'!$B$1:$D$206,3,FALSE) -> AFR | D39: =VLOOKUP(B39,'[2]Metadata - Countries'!$A$1:$B$266,2,FALSE) -> Sub-Saharan Africa | E39: =VLOOKUP(B39,'[2]Metadata - Countries'!$A$1:$C$266,3,FALSE) -> Low income | G39: 13.846294 | H39: =VLOOKUP(B39,[4]tas!$A$2:$H$247,5,FALSE) -> 26.69 | I39: =VLOOKUP(B39,[4]tas!$A$2:$H$247,6,FALSE) -> 26.7 | J39: =VLOOKUP(B39,[4]tas!$A$2:$H$247,7,FALSE) -> 26.83 | K39: 2.3826186e+09 | L39: 2.5554921e+09 | M39: 2.7515445e+09 | N39: =VLOOKUP(B39,[2]Data!$B$1:$G$267,4,FALSE) -> 467.35983 | O39: =VLOOKUP(B39,[2]Data!$B$1:$G$267,5,FALSE) -> 495.9789 | P39: =VLOOKUP(B39,[2]Data!$B$1:$G$267,6,FALSE) -> 516.161 | Q39: =VLOOKUP(B39,[5]Sheet1!$B$421:$K$628,10,FALSE) -> 0 | R39: =VLOOKUP(B39,[5]Sheet1!$B$213:$K$420,10,FALSE) -> 0 | S39: =VLOOKUP(B39,[5]Sheet1!$B$2:$K$207,10,FALSE) -> 0 | T39: =VLOOKUP(B39,[6]Sheet1!$B$421:$K$628,10,FALSE) -> 0 | U39: =VLOOKUP(B39,[6]Sheet1!$B$213:$K$420,10,FALSE) -> 0 | V39: =VLOOKUP(B39,[6]Sheet1!$B$2:$K$212,10,FALSE) -> 0 | W39: 0 | X39: 0 | Y39: 0 | Z39: 34.433418 | AA39: 49.215233 | AB39: 49.166445 | AC39: 49.003361 | AD39: 2.1436966 | AE39: 2.0952774 | AF39: 2.1510726 | AG39: 8.1833109 | AH39: 8.2706042 | AI39: =VLOOKUP(B39,[7]all!$A$2:$I$247,6,FALSE) -> 64.74 | AJ39: =VLOOKUP(B39,[7]all!$A$2:$I$247,7,FALSE) -> 64.63 | AK39: =VLOOKUP(B39,[7]all!$A$2:$I$247,8,FALSE) -> 64.54
A40: Chad | B40: TCD | C40: =VLOOKUP(B40,'[1]who-regions'!$B$1:$D$206,3,FALSE) -> AFR | D40: =VLOOKUP(B40,'[2]Metadata - Countries'!$A$1:$B$266,2,FALSE) -> Sub-Saharan Africa | E40: =VLOOKUP(B40,'[2]Metadata - Countries'!$A$1:$C$266,3,FALSE) -> Low income | G40: 12.922066 | H40: =VLOOKUP(B40,[4]tas!$A$2:$H$247,5,FALSE) -> 27.7 | I40: =VLOOKUP(B40,[4]tas!$A$2:$H$247,6,FALSE) -> 27.65 | J40: =VLOOKUP(B40,[4]tas!$A$2:$H$247,7,FALSE) -> 27.83 | K40: 1.7828508e+10 | L40: 1.9107685e+10 | M40: 2.0625712e+10 | N40: =VLOOKUP(B40,[2]Data!$B$1:$G$267,4,FALSE) -> 966.03647 | O40: =VLOOKUP(B40,[2]Data!$B$1:$G$267,5,FALSE) -> 949.33345 | P40: =VLOOKUP(B40,[2]Data!$B$1:$G$267,6,FALSE) -> 961.55976 | Q40: =VLOOKUP(B40,[5]Sheet1!$B$421:$K$628,10,FALSE) -> 0 | R40: =VLOOKUP(B40,[5]Sheet1!$B$213:$K$420,10,FALSE) -> 0 | S40: =VLOOKUP(B40,[5]Sheet1!$B$2:$K$207,10,FALSE) -> 0 | T40: =VLOOKUP(B40,[6]Sheet1!$B$421:$K$628,10,FALSE) -> 0 | U40: =VLOOKUP(B40,[6]Sheet1!$B$213:$K$420,10,FALSE) -> 0 | V40: =VLOOKUP(B40,[6]Sheet1!$B$2:$K$212,10,FALSE) -> 0 | W40: 0 | X40: 0 | Y40: 0 | Z40: 49.138848 | AA40: 47.403703 | AB40: 46.737174 | AC40: 46.064628 | AD40: 2.0555108 | AE40: 2.0747744 | AF40: 2.1005366 | AG40: 14.656382 | AH40: 15.342332 | AI40: =VLOOKUP(B40,[7]all!$A$2:$I$247,6,FALSE) -> 32.2 | AJ40: =VLOOKUP(B40,[7]all!$A$2:$I$247,7,FALSE) -> 32.02 | AK40: =VLOOKUP(B40,[7]all!$A$2:$I$247,8,FALSE) -> 32.17
...

Sheet country
A1: Country Name | B1: Country Code | C1: WHO_region | D1: WB_region | E1: BBS_pop_2022 | F1: AvgSAT_2022 | G1: AvgSAT_2023 | H1: AvgSAT_2024 | I1: AvgSAT | J1: GDP_2022 | K1: GDP_2023 | L1: GDP_2024 | M1: GDP | N1: perGDP_2022 | O1: perGDP_2023 | P1: perGDP_2024 | Q1: InfVax6m_2022 | R1: InfVax6m_2023 | S1: InfVax6m_2024 | T1: IVC65p_2022 | U1: IVC65p_2023 | V1: IVC65p_2024 | W1: PLGP_2022 | X1: PLGP_2023 | Y1: PLGP_2024 | Z1: PM_2020 | AA1: p14p_2022 | AB1: p14p_2023 | AC1: p14p_2024 | AD1: p65p_2022 | AE1: p65p_2023 | AF1: p65p_2024 | AG1: PopDens_2022 | AH1: PopDens_2023 | AI1: re_2022 | AJ1: re_2023 | AK1: re_2024 | AL1: INT_ARR_2022
A2: Argentina | B2: ARG | C2: AMR | D2: =VLOOKUP(B2,global!B1:D218,3,FALSE) -> Latin America & Caribbean | E2: 0 | F2: 15.52 | G2: 15.52 | H2: 15.65 | I2: =AVERAGE(F2:H2) -> 15.563333 | J2: =VLOOKUP(B2,global!B1:P218,7,FALSE) -> 15.52 | K2: =VLOOKUP(B2,global!B1:P218,8,FALSE) -> 15.52 | L2: =VLOOKUP(B2,global!B1:P218,9,FALSE) -> 15.65 | M2: =AVERAGE(J2:L2) -> 15.563333 | N2: =VLOOKUP(B2,global!B1:P218,10,FALSE) -> 6.3279007e+11 | O2: =VLOOKUP(B2,global!B1:P218,11,FALSE) -> 6.4607528e+11 | P2: =VLOOKUP(B2,global!B1:P218,12,FALSE) -> 6.3326669e+11 | Q2: 0 | R2: 0 | S2: 0 | T2: 75.85 | U2: 12.19 | V2: 0 | W2: 0 | X2: 0 | Y2: 0 | Z2: 14.908174 | AA2: 22.750746 | AB2: 22.190657 | AC2: 21.603943 | AD2: 12.03408 | AE2: 12.203022 | AF2: 12.416004 | AG2: 16.592272 | AH2: 16.639956 | AI2: 58.82 | AJ2: 58.82 | AK2: 58.14 | AL2: 113132.4
A3: Australia | B3: AUS | C3: WPR | D3: =VLOOKUP(B3,global!B2:D219,3,FALSE) -> East Asia & Pacific | E3: 100 | F3: 22.83 | G3: 22.86 | H3: 22.94 | I3: =AVERAGE(F3:H3) -> 22.876667 | J3: =VLOOKUP(B3,global!B2:P219,7,FALSE) -> 22.83 | K3: =VLOOKUP(B3,global!B2:P219,8,FALSE) -> 22.86 | L3: =VLOOKUP(B3,global!B2:P219,9,FALSE) -> 22.94 | M3: =AVERAGE(J3:L3) -> 22.876667 | N3: =VLOOKUP(B3,global!B2:P219,10,FALSE) -> 1.6908582e+12 | O3: =VLOOKUP(B3,global!B2:P219,11,FALSE) -> 1.7280573e+12 | P3: =VLOOKUP(B3,global!B2:P219,12,FALSE) -> 1.7521933e+12 | Q3: 0 | R3: 0 | S3: 0 | T3: 0 | U3: 0 | V3: 61.1 | W3: 0 | X3: 0 | Y3: 0 | Z3: 8.2517175 | AA3: 18.235542 | AB3: 18.030283 | AC3: 17.841848 | AD3: 17.075032 | AE3: 17.384025 | AF3: 17.730016 | AG3: 3.3819984 | AH3: 3.4649906 | AI3: 47.17 | AJ3: 47.01 | AK3: 46.84 | AL3: 309626
A4: Belgium | B4: BEL | C4: EUR | D4: =VLOOKUP(B4,global!B3:D220,3,FALSE) -> Europe & Central Asia | E4: 99.486217 | F4: 10.78 | G4: 10.6 | H4: 10.65 | I4: =AVERAGE(F4:H4) -> 10.676667 | J4: =VLOOKUP(B4,global!B3:P220,7,FALSE) -> 10.78 | K4: =VLOOKUP(B4,global!B3:P220,8,FALSE) -> 10.6 | L4: =VLOOKUP(B4,global!B3:P220,9,FALSE) -> 10.65 | M4: =AVERAGE(J4:L4) -> 10.676667 | N4: =VLOOKUP(B4,global!B3:P220,10,FALSE) -> 5.9361457e+11 | O4: =VLOOKUP(B4,global!B3:P220,11,FALSE) -> 6.4465528e+11 | P4: =VLOOKUP(B4,global!B3:P220,12,FALSE) -> 6.6456418e+11 | Q4: 0 | R4: 0 | S4: 0 | T4: 57.3 | U4: 0 | V4: 0 | W4: 0 | X4: 0 | Y4: 0 | Z4: 11.216066 | AA4: 16.529679 | AB4: 16.290745 | AC4: 15.996127 | AD4: 19.767193 | AE4: 20.145275 | AF4: 20.558081 | AG4: 383.03306 | AH4: 386.54893 | AI4: 80.15 | AJ4: 80.3 | AK4: 80.08
A5: Brazil | B5: BRA | C5: AMR | D5: =VLOOKUP(B5,global!B4:D221,3,FALSE) -> Latin America & Caribbean | E5: 90.883499 | F5: 26.04 | G5: 26.06 | H5: 26.1 | I5: =AVERAGE(F5:H5) -> 26.066667 | J5: =VLOOKUP(B5,global!B4:P221,7,FALSE) -> 26.04 | K5: =VLOOKUP(B5,global!B4:P221,8,FALSE) -> 26.06 | L5: =VLOOKUP(B5,global!B4:P221,9,FALSE) -> 26.1 | M5: =AVERAGE(J5:L5) -> 26.066667 | N5: =VLOOKUP(B5,global!B4:P221,10,FALSE) -> 1.9519239e+12 | O5: =VLOOKUP(B5,global!B4:P221,11,FALSE) -> 2.1911318e+12 | P5: =VLOOKUP(B5,global!B4:P221,12,FALSE) -> 2.1794121e+12 | Q5: 0 | R5: 0 | S5: 0 | T5: 70.24 | U5: 63.3 | V5: 45.4 | W5: 0 | X5: 0 | Y5: 0 | Z5: 12.179325 | AA5: 20.202477 | AB5: 19.935952 | AC5: 19.66514 | AD5: 10.251785 | AE5: 10.633631 | AF5: 11.049184 | AG5: 25.161868 | AH5: 25.261688 | AI5: 72.82 | AJ5: 72.67 | AK5: 72.76
